Workbook

Sheet Asset Register
A1: REIT | B1: SPV / Holding entity | C1: Property / Asset | D1: Type | E1: City | F1: Locality / Area | G1: Micro-market (valuer) | H1: Address | I1: Leasable (sq ft) | J1: Leasable (msf) | K1: Completed (msf) | L1: Committed occ. | M1: In-place occ. | N1: Market rent /sqft/mo | O1: In-place rent /sqft/mo | P1: Rent reversion | Q1: WALE (yrs) | R1: Tenants | S1: Cap rate | T1: Discount rate | U1: Market value (INR cr) | V1: Value/sqft (INR) | W1: Mgmt fee (valuation DCF) | X1: Insurance (valuation DCF) | Y1: Notes / source
A2: Embassy | B2: Manyata Promoters Private Limited (MPPL) | C2: Embassy Manyata | D2: Office | E2: Bengaluru | F2: Nagawara / Hebbal | G2: Peripheral North (Outer Ring Road / Hebbal stretch) | H2: Along Outer Ring Road, Nagawara, Bengaluru, Karnataka; land approx. 119.15 acres | I2: 17200000 | J2: 17.2 | K2: 14.6 | M2: 0.94 | N2: 105 | O2: 95 | P2: =IF(OR(N2="",O2="",O2=0),"",N2/O2-1) | Q2: 8.8 | S2: 0.08 | T2: 0.12 | U2: 27868.9 | V2: =IF(OR(U2="",I2="",I2=0),"",U2*10000000/I2) | W2: Property Management Fees = 3% of Total Income (lease rentals, parking, fitout, other operating income) | X2: INR 0.3/sqft/mo; property tax & insurance escalated 3% p.a. | Y2: Mixed-use: completed office 14.6 msf + UC/proposed office 2.6 msf + Hotel (5-star 266 keys, 3-star 353 keys). Value split: completed 242,591 + UC/proposed 17,026 + hotel 19,072. Cap rate 8% office/retail, 7.14% hospitality; discount rate 11.5% operational office, 12.75% UC, 11.90% hospitality (reported field uses office cap 8% / operational discount ~11.5-12.75, rounded to 12). Retail mkt rent 105, anchor 94.5. Blocks M3A/M3B on leasehold land from EPDPL. Source lines ~9433-10476, value summary L4237.
A3: Embassy | B3: Vikas Telecom Private Limited (VTPL) & Sarla Infrastructure Private Limited (SIPL) | C3: Embassy TechVillage | D3: Office | E3: Bengaluru | F3: Bellandur | G3: Outer Ring Road (Sarjapura-Marathahalli), Bellandur-Marathahalli | H3: Devarabeesanahalli Village & Kariyamanna Agrahara Village, Varthur Hobli, Bengaluru East Taluk, Karnataka; land approx. 84.05 acres under purview | I3: 9700000 | J3: 9.7 | K3: 9.2 | M3: 0.95 | N3: 105 | O3: 90 | P3: =IF(OR(N3="",O3="",O3=0),"",N3/O3-1) | Q3: 9.5 | S3: 0.08 | T3: 0.12 | U3: 16624.6 | V3: =IF(OR(U3="",I3="",I3=0),"",U3*10000000/I3) | W3: Property Management Fees = 3% of Total Income | X3: INR 0.21/sqft/mo | Y3: Mixed-use: completed office 9.2 msf + UC office 0.4 msf + 2 UC hotels (5-star 311 keys, 3-star 207 keys). Value split: completed 153,974 + UC/proposed 4,258 + hotel 8,014. Cap 8% office/retail, 7.14% hospitality; discount 11.5% operational, 12.75% UC office, 13.25% UC hotel. Retail mkt rent 90. SIPL portion (1.2 msf, Block 9) BTS to JP Morgan. Source lines ~10477-11428.
A4: Embassy | B4: GolfLinks Software Park Private Limited (GLSP, 50% JV) + Eleanor Realty Holdings India Private Limited (ERHIPL, Pinehurst 100%) | C4: Embassy GolfLinks (incl. Pinehurst) | D4: Office | E4: Bengaluru | F4: Domlur | G4: Suburban East (Intermediate Ring Road, near CBD) | H4: Challaghatta Village, Varthur Hobli, Mahadevapura, Bengaluru East Taluk 560071; land approx. 37.1 acres | I4: 3400000 | J4: 3.4 | K4: 3.4 | M4: 1 | N4: 170 | O4: 160 | P4: =IF(OR(N4="",O4="",O4=0),"",N4/O4-1) | Q4: 10 | S4: 0.08 | T4: 0.12 | U4: 5129.8 | V4: =IF(OR(U4="",I4="",I4=0),"",U4*10000000/I4) | W4: Property Management Fees = 3% of Total Income (both GolfLinks and Pinehurst) | X4: GolfLinks INR 0.3/sqft/mo; Pinehurst INR 0.5/sqft/mo | Y4: 100% property value = GolfLinks 84,937 + Pinehurst 8,829 = 93,766; REIT economic interest = 50% of GolfLinks + 100% Pinehurst = 51,298 (this is the share-of-total value shown in the portfolio summary). Cap 7.75% office/retail; discount 11.5% operational. Pinehurst (0.3 msf) acquired via 100% Eleanor Realty stake Q3 FY2026: mkt rent 180, in-place 167 (192 as of 1-Apr-2026). GolfLinks office mkt rent 170, in-place 160; retail mkt rent 55. cap_rate field records 7.75 rounded to 8. Source lines ~11429-12099; summary L4288.
A5: Embassy | B5: Quadron Business Park Private Limited (QBPL) | C5: Embassy One | D5: Office | E5: Bengaluru | F5: Bellary Road (Mekhri Circle) | G5: Peripheral North (between Hebbal and off-CBD) | H5: Embassy One, Bellary Road, Ganga Nagar, Bengaluru, Karnataka; land approx. 5.6 acres (3.2 acres under valuation scope) | I5: 300000 | J5: 0.3 | K5: 0.3 | M5: 1 | N5: 151 | O5: 151 | P5: =IF(OR(N5="",O5="",O5=0),"",N5/O5-1) | Q5: 7.6 | S5: 0.08 | T5: 0.12 | U5: 1572 | V5: =IF(OR(U5="",I5="",I5=0),"",U5*10000000/I5) | W5: Property Management Fees = 3% of Total Income | X5: INR 0.4/sqft/mo | Y5: Mixed-use: completed office 0.3 msf (Pinnacle tower) + Four Seasons hotel 230 keys (5-star). Value split: office 5,902 + hotel 9,818 = 15,720. Cap 7.75% office, 7.14% hospitality (recorded 8, rounded); discount 11.5% operational, 11.90% hospitality. Office mkt rent = in-place 151 (incl. car park). Residential apartments excluded. Vacancy provision 5%. SPV Quadron Business Park Pvt Ltd (same SPV that owns Embassy Quadron Pune). Source lines ~12100-12800.
A6: Embassy | B6: Embassy Construction Private Limited (ECPL) | C6: Embassy Business Hub | D6: Office | E6: Bengaluru | F6: Yelahanka | G6: Peripheral North / North Bengaluru (Yelahanka-Devanahalli) | H6: Sy. No. 25/2, 25/3 & 26, Venkatala Village, Bellary Road (NH-44), Yelahanka, Bengaluru North, Karnataka; JDA land approx. 13 acres | I6: 1400000 | J6: 1.4 | K6: 0.4 | N6: 69 | O6: 58 | P6: =IF(OR(N6="",O6="",O6=0),"",N6/O6-1) | R6: 1 | S6: 0.08 | T6: 0.12 | U6: 722.4 | V6: =IF(OR(U6="",I6="",I6=0),"",U6*10000000/I6) | W6: Property Management Fees = 3% of Total Income | X6: INR 0.25/sqft/mo | Y6: REIT share (developer share under JDA) approx. 1.4 msf: Phase I completed 0.4 msf (single tenant Philips India, lease to Nov 2038) + Phase II UC 1.0 msf (completion FY2028). Value split: Phase I 4,652 + Phase II UC 2,572 = 7,224. Cap 8%; discount 11.5% Phase I operational, 12.75% Phase II UC. SPV named from consolidated AR/FS (ECPL) - valuation report showed only JDA ownership, no explicit Entity line. Phase II pending dev cost INR 6,569 Mn. Source lines ~12802-13413; AR L1275/7021.
A7: Embassy | B7: Indian Express Newspapers (Mumbai) Private Limited (IENMPL) | C7: Express Towers | D7: Office | E7: Mumbai | F7: Nariman Point | G7: South Mumbai CBD (Nariman Point) | H7: Plot No. 236, Block III of Backbay Reclamation Estate, Barrister Rajni Patel Marg, Nariman Point, Mumbai; land approx. 1.5 acres (freehold) | I7: 500000 | J7: 0.5 | K7: 0.5 | M7: 1 | N7: 350 | O7: 296 | P7: =IF(OR(N7="",O7="",O7=0),"",N7/O7-1) | Q7: 4 | S7: 0.08 | T7: 0.12 | U7: 2449.9 | V7: =IF(OR(U7="",I7="",I7=0),"",U7*10000000/I7) | W7: Property Management Fees = 3% of Total Income | X7: INR 0.4/sqft/mo | Y7: Completed office 0.5 msf (= total). Cap 7.5% (recorded 8, rounded); discount 11.5% operational. Office mkt rent revised 300->350; in-place 296. Age ~56 yrs, LEED Platinum. Acquisition price INR 18,385 Mn (related party). Source lines ~13414-13934.
A8: Embassy | B8: Vikhroli Corporate Park Private Limited (VCPPL) | C8: Embassy 247 | D8: Office | E8: Mumbai | F8: Vikhroli West | G8: Eastern Suburbs (Vikhroli West) | H8: Hariyali Village, Kurla Taluka, Lal Bahadur Shastri (LBS) Road, Gandhi Nagar, Vikhroli West, Mumbai; land approx. 7.3 acres (freehold) | I8: 1200000 | J8: 1.2 | K8: 1.2 | M8: 1 | N8: 135 | O8: 118 | P8: =IF(OR(N8="",O8="",O8=0),"",N8/O8-1) | Q8: 3.1 | S8: 0.08 | T8: 0.12 | U8: 2243.7 | V8: =IF(OR(U8="",I8="",I8=0),"",U8*10000000/I8) | W8: Property Management Fees = 3% of Total Income | X8: INR 0.3/sqft/mo | Y8: Completed office 1.2 msf (3 towers A/B/C). Cap 8%; discount 11.5% operational. Office mkt rent revised 121->135; retail mkt rent 250; in-place 118. LEED Platinum. Acquisition price INR 16,727 Mn (related party). Source lines ~13935-14458.
A9: Embassy | B9: Earnest Towers Private Limited (ETPL) | C9: First International Financial Centre (FIFC) | D9: Office | E9: Mumbai | F9: Bandra Kurla Complex | G9: Bandra Kurla Complex (BKC) / Secondary Business District, G Block | H9: Plot No. C-54 & C-55, G Block, BKC Road, Bandra Kurla Complex, Mumbai 400 051; leasehold land from MMRDA, approx. 2.0 acres | I9: 400000 | J9: 0.4 | K9: 0.4 | M9: 1 | N9: 350 | O9: 325 | P9: =IF(OR(N9="",O9="",O9=0),"",N9/O9-1) | Q9: 3.5 | S9: 0.08 | T9: 0.12 | U9: 1840.6 | V9: =IF(OR(U9="",I9="",I9=0),"",U9*10000000/I9) | W9: Property Management Fees = 3% of Total Income | X9: INR 0.1/sqft/mo | Y9: Leasehold interest in ~226,663 sqft (2 basements, part ground+1st, entire 2nd-7th floors) with 54.2% undivided land share. Cap 7.5% (recorded 8, rounded); discount 11.5% operational. Office mkt rent revised 320->350; retail mkt rent revised 350->425; in-place 325. High property tax INR 12.0/sqft/mo. LEED Platinum. Acquisition price INR 14,614 Mn. Source lines ~14459-15003.
A10: Embassy | B10: Embassy Pune TechZone Private Limited (EPTPL) | C10: Embassy TechZone | D10: Office | E10: Pune | F10: Hinjewadi Phase 2 | G10: PBD West / Hinjewadi Phase 2 | H10: Plot No. 3A, Hinjewadi Phase 2 Road, Hinjewadi Rajiv Gandhi Infotech Park, Hinjewadi, Pune, Maharashtra 411057; land approx. 67.5 acres (leasehold) | I10: 5500000 | J10: 5.5 | K10: 3 | M10: 0.77 | N10: 50 | O10: 54 | P10: =IF(OR(N10="",O10="",O10=0),"",N10/O10-1) | Q10: 5.6 | S10: 0.08 | T10: 0.12 | U10: 2592.4 | V10: =IF(OR(U10="",I10="",I10=0),"",U10*10000000/I10) | W10: Property Management Fees = 3% of Total Income; Asset Mgmt fee booked below NOI | X10: INR 0.2/sqft/mo | Y10: Mixed-use: completed office 3.0 msf + UC/proposed office 2.4 msf + 116-key hotel. Value split: completed 23,235 + UC/proposed 2,450 + hotel 239. Cap 8.25% office (recorded 8, rounded), 7.14% hospitality; discount 11.5% operational, 12.75% UC office, 13.25% UC hotel. Occupancy may fall to 73% if a domestic tech tenant exits 1-Apr-2026. Acquisition price INR 20,720 Mn. Source lines ~15004-15839.
A11: Embassy | B11: Quadron Business Park Private Limited (QBPL) | C11: Embassy Quadron | D11: Office | E11: Pune | F11: Hinjewadi Phase 2 | G11: PBD West / Hinjewadi Phase 2 | H11: Plot No. 28, Hinjewadi Phase 2 Road, Hinjewadi Rajiv Gandhi Infotech Park, Pimpri-Chinchwad, Pune, Maharashtra 411057; land approx. 25.5 acres (leasehold) | I11: 1900000 | J11: 1.9 | K11: 1.9 | M11: 0.24 | N11: 46 | O11: 56 | P11: =IF(OR(N11="",O11="",O11=0),"",N11/O11-1) | Q11: 4.3 | S11: 0.08 | T11: 0.12 | U11: 1003.9 | V11: =IF(OR(U11="",I11="",I11=0),"",U11*10000000/I11) | W11: Property Management Fees = 3% of Total Income; Asset Mgmt fee below NOI | X11: INR 0.2/sqft/mo | Y11: Completed office 1.9 msf (all completed, no UC). Cap 8.25% (recorded 8, rounded); discount 11.5% operational. Very low occupancy 24%. Office mkt rent 46, in-place 56. Same SPV as Embassy One (Bengaluru). Acquisition price INR 13,961 Mn. Source lines ~15840-16388.
A12: Embassy | B12: Qubix Business Park Private Limited (QBPPL) | C12: Embassy Qubix | D12: Office | E12: Pune | F12: Hinjewadi Phase 1 | G12: PBD West / Hinjewadi Phase 1 | H12: Blue Ridge Township, Phase 1, Hinjewadi Rajiv Gandhi Infotech Park, Pimpri-Chinchwad, Pune, Maharashtra 411057; land approx. 25.2 acres (freehold) | I12: 1500000 | J12: 1.5 | K12: 1.5 | M12: 0.78 | N12: 50 | O12: 51 | P12: =IF(OR(N12="",O12="",O12=0),"",N12/O12-1) | Q12: 4.2 | S12: 0.08 | T12: 0.12 | U12: 1048.3 | V12: =IF(OR(U12="",I12="",I12=0),"",U12*10000000/I12) | W12: Property Management Fees = 3% of Total Income; Asset Mgmt fee below NOI | X12: INR 0.3/sqft/mo | Y12: Completed office 1.5 msf (5 SEZ + 1 Non-SEZ block). Cap 8.25% (recorded 8, rounded); discount 11.5% operational. Only freehold Pune asset. Office mkt rent 50, in-place 51. Acquisition price INR 9,868 Mn. Source lines ~16389-16936.
A13: Embassy | B13: Oxygen Business Park Private Limited (OBPPL) | C13: Embassy Oxygen | D13: Office | E13: Noida | F13: Noida-Greater Noida Expressway | G13: Noida-Greater Noida Expressway (Sector 144) | H13: Plot No. 7, Sector-144, Noida, Uttar Pradesh; land approx. 24.8 acres, leasehold from NOIDA Authority | I13: 3300000 | J13: 3.3 | K13: 3.3 | M13: 0.9 | N13: 59 | O13: 57 | P13: =IF(OR(N13="",O13="",O13=0),"",N13/O13-1) | Q13: 9.1 | S13: 0.08 | T13: 0.12 | U13: 2951.8 | V13: =IF(OR(U13="",I13="",I13=0),"",U13*10000000/I13) | W13: Property Management Fees = 3% of Total Income (booked below NOI) | X13: INR 0.22/sqft/mo; plus Land Lease Payment INR 0.38/sqft/mo (in lieu of property tax) | Y13: Completed office 3.3 msf (10 buildings incl food court). Cap 8%; discount 11.5% operational. Office mkt rent 59 (incl parking), in-place 57; retail mkt rent 85. Seismic Zone IV. Acquisition price INR 18,258 Mn. Source lines ~16937-17515.
A14: Embassy | B14: Galaxy Square Private Limited (GSPL) | C14: Embassy Galaxy | D14: Office | E14: Noida | F14: Noida Sector 62 | G14: Noida Sector 62 | H14: A-44 & 45, Sector-62, Noida, Uttar Pradesh; land approx. 9.9 acres, leasehold from NOIDA Authority | I14: 1400000 | J14: 1.4 | K14: 1.4 | M14: 1 | N14: 51 | O14: 46 | P14: =IF(OR(N14="",O14="",O14=0),"",N14/O14-1) | Q14: 9.5 | S14: 0.08 | T14: 0.12 | U14: 1131.1 | V14: =IF(OR(U14="",I14="",I14=0),"",U14*10000000/I14) | W14: Property Management Fees = 3% of Total Income (below NOI) | X14: INR 0.27/sqft/mo; Land Lease Payment INR 0.34/sqft/mo | Y14: Completed office 1.4 msf (5 Non-SEZ blocks). Rent roll ~99.6% occupied. Cap 8%; discount 11.5% operational. Office mkt rent 51 (incl parking), in-place 46; retail mkt rent 85. LEED Platinum. Acquisition price INR 8,122 Mn. Source lines ~17516-18059.
A15: Embassy | B15: Umbel Properties Private Limited (UPPL) | C15: Hilton at Embassy GolfLinks | D15: Hotel | E15: Bengaluru | F15: Domlur | G15: Suburban East (inside Embassy GolfLinks Business Park, Intermediate Ring Road) | H15: Challaghatta Village, Varthur Hobli, Bengaluru East Taluk 560071; land approx. 3.6 acres (freehold) | I15: 500000 | J15: 0.5 | K15: 0.5 | M15: 0.72 | P15: =IF(OR(N15="",O15="",O15=0),"",N15/O15-1) | S15: 0.07 | T15: 0.12 | U15: 887.6 | V15: =IF(OR(U15="",I15="",I15=0),"",U15*10000000/I15) | W15: Base Management Fee 2% of Total Revenue; Management Incentive Fee 5.5% of Gross Operating Profit; FF&E reserve 2% | Y15: 247-key 5-star hotel (developed area ~0.5 msf). Stabilized occupancy 72% (FY2026); ADR INR 15,000/room/night +5% YoY from Oct 2026; F&B revenue 40% of rooms revenue. Cap rate 7.14% derived via EV/EBITDA 14x (recorded 7, rounded); discount rate 11.90% (recorded 12, rounded). No psf rent (hotel). Acquisition price INR 4,766 Mn. Source lines ~18060-18516.
A16: Embassy | B16: ESNP Property Builders and Developers Private Limited (ESNP) | C16: Embassy Splendid Techzone | D16: Office | E16: Chennai | F16: Pallavaram | G16: Suburban South (Pallavaram-Thoraipakkam Road) | H16: Pallavaram-Thoraipakkam (PTR) Road, Pallavaram, Chennai, Tamil Nadu; land approx. 25.37 acres (leasehold from SNP) | I16: 5100000 | J16: 5.1 | K16: 2.5 | M16: 0.84 | N16: 75 | O16: 73 | P16: =IF(OR(N16="",O16="",O16=0),"",N16/O16-1) | Q16: 11.5 | S16: 0.08 | T16: 0.12 | U16: 2058.7 | V16: =IF(OR(U16="",I16="",I16=0),"",U16*10000000/I16) | W16: Property Management Fees = 3% of Total Income (below NOI) | X16: INR 0.13/sqft/mo | Y16: Mixed-use (IT/ITeS SEZ/Non-SEZ): completed 2.5 msf + UC/proposed 2.6 msf. Value split: completed 15,556 + UC 5,031 = 20,587. Cap 8% office/retail; discount 11.5% operational office. Office mkt rent 75 (incl parking), in-place 73; retail mkt rent 25. Land freehold of SNP granting leasehold to ESNP (30 yrs from 9-Nov-2016, renewable). Pending dev cost ~INR 8,083 Mn. Acquisition price INR 11,853 Mn. Source lines ~18517-19186.
A17: Embassy | B17: Embassy Energy Private Limited (EEPL) | C17: Embassy Energy (Solar Park) | D17: Other | E17: Bellary District, Karnataka | F17: Villages Ittigi & Mooregeri and Nellukudure | G17: Villages Ittigi & Mooregeri (Huvinhadagali Taluka) and Nellukudure (Hagribommanhalli Taluka) | H17: Bellary District, Karnataka; primary access SH-45; land approx. 465.8 acres | P17: =IF(OR(N17="",O17="",O17=0),"",N17/O17-1) | T17: 0.12 | U17: 414.3 | V17: =IF(OR(U17="",I17="",I17=0),"",U17*10000000/I17) | Y17: Solar Park: installed capacity 130 MW DC / 100 MW AC; commissioned Feb 2018; ~215 MU/yr; CUF 17.35%. No leasable area or psf rent. Discount rate 11.5% (recorded 12, rounded); no cap rate (25-yr DCF over CERC useful life, no terminal cap). PPA tariff FY2027 INR 6.83/unit, escalation 2.5%/yr; 25-yr PPAs with Embassy office parks/hotels (Manyata, GolfLinks, Hilton GolfLinks, TechVillage) plus C&I offtakers. O&M INR 18.3 Mn/qtr. No property mgmt fee (admin/O&M/employee costs instead). SPV labelled 'Power Limited' in one value table (likely typo for Private Limited). Acquisition price INR 10,690 Mn. Source lines ~19187-19981.
A18: Mindspace | B18: Sundew Properties Limited | C18: Mindspace Madhapur (Sundew) | D18: Office | E18: Hyderabad | F18: Madhapur | G18: Madhapur | H18: Mindspace Madhapur, Titus Towers, TSIIC software layout, Madhapur, Hyderabad, Telangana 500081 | I18: 5870000 | J18: 5.87 | K18: 5.87 | L18: 0.99 | M18: 0.96 | N18: 105 | O18: 75.58 | P18: =IF(OR(N18="",O18="",O18=0),"",N18/O18-1) | Q18: 7.84 | R18: 51 | S18: 0.08 | T18: 0.12 | U18: 7963.812 | V18: =IF(OR(U18="",I18="",I18=0),"",U18*10000000/I18) | Y18: Grade A IT Park, 8 buildings (Non-SEZ 11,22; SEZ rest); Bldg 22 hotel. MREIT 89% interest (100% value INR89,481.03mn). Exit cap 7.75%, WACC 11.75%. Occ 96.3%/committed 98.7%. Land 40.25 ac freehold. p.1-52 (chunk a)
A19: Mindspace | B19: K Raheja IT Park (Hyderabad) Limited | C19: Mindspace Madhapur (KRIT) | D19: Office | E19: Hyderabad | F19: Madhapur | G19: Madhapur | H19: Mindspace Madhapur (KRIT), Madhapur, Hyderabad, Telangana 500081 | I19: 5940000 | J19: 5.94 | K19: 2.18 | L19: 0.99 | M19: 0.97 | N19: 105 | O19: 79.96 | P19: =IF(OR(N19="",O19="",O19=0),"",N19/O19-1) | Q19: 7.24 | R19: 29 | S19: 0.08 | T19: 0.12 | U19: 5982.4 | V19: =IF(OR(U19="",I19="",I19=0),"",U19*10000000/I19) | Y19: IT Park Non-SEZ (incl retail). Exit cap 7.75%, WACC 11.75%. Occ 96.5%/committed 99.2%. Land 48.43 ac freehold. chunk a
A20: Mindspace | B20: Intime Properties Limited | C20: Mindspace Madhapur (Intime) | D20: Office | E20: Hyderabad | F20: Madhapur | G20: Madhapur | H20: Mindspace Madhapur (Intime), Madhapur, Hyderabad, Telangana 500081 | I20: 2030000 | J20: 2.03 | K20: 2.03 | L20: 1 | M20: 1 | N20: 105 | O20: 79.06 | P20: =IF(OR(N20="",O20="",O20=0),"",N20/O20-1) | Q20: 7.08 | R20: 35 | S20: 0.08 | T20: 0.12 | U20: 2855.721 | V20: =IF(OR(U20="",I20="",I20=0),"",U20*10000000/I20) | Y20: IT Park Non-SEZ. Exit cap 7.75%, WACC 11.75%. Occ 99.8%/committed 99.8%. Land 8.52 ac freehold. chunk a
A21: Mindspace | B21: Mindspace Business Parks Private Limited | C21: Mindspace Pocharam | D21: Other | E21: Hyderabad | F21: Pocharam | G21: Pocharam (PBD East / Suburbs Other) | H21: Mindspace Pocharam, Hyderabad – Non-SEZ IT Park | I21: 570000 | J21: 0.57 | K21: 0.57 | L21: 0 | M21: 0 | P21: =IF(OR(N21="",O21="",O21=0),"",N21/O21-1) | R21: 0 | U21: 100.435 | V21: =IF(OR(U21="",I21="",I21=0),"",U21*10000000/I21) | Y21: Non-SEZ IT Park; built component 0.57 msf currently VACANT (NIL occupancy/tenants) + undeveloped land held at land value. Valued via Land & Building/DCF hybrid; land ~INR30.49mn/acre. Land 26.464 ac freehold. chunk a
A22: Mindspace | B22: Sustain Properties Private Limited | C22: Commerzone Raidurg (Sustain) | D22: Office | E22: Hyderabad | F22: Madhapur | G22: Madhapur (Raidurg) | H22: Commerzone Raidurg (Sustain), Madhapur, Hyderabad, Telangana 500081 | I22: 1820000 | J22: 1.82 | K22: 1.82 | L22: 1 | M22: 1 | O22: 69.1 | P22: =IF(OR(N22="",O22="",O22=0),"",N22/O22-1) | Q22: 10.5 | R22: 2 | S22: 0.08 | T22: 0.12 | U22: 2585.322 | V22: =IF(OR(U22="",I22="",I22=0),"",U22*10000000/I22) | Y22: SEZ IT/ITeS. Exit cap 7.75%, WACC 11.75%. Occ 100%/committed 100%. Sustain entitled 65.5% undivided share of 9.07 ac land. Market rent per JLL (not a single psf figure in exec summary). chunk a
A23: Mindspace | B23: Mack Soft Tech Private Limited | C23: The Square, Financial District (Hyderabad) | D23: Office | E23: Hyderabad | F23: Gachibowli | G23: Gachibowli / Nanakramguda (Financial District) | H23: The Square, 110 Financial District, Nanakramguda, Hyderabad, Telangana 500032 | I23: 820000 | J23: 0.82 | K23: 0.82 | L23: 0.72 | M23: 0.62 | N23: 60 | O23: 60 | P23: =IF(OR(N23="",O23="",O23=0),"",N23/O23-1) | Q23: 3.4 | R23: 25 | S23: 0.08 | T23: 0.12 | U23: 707.727 | V23: =IF(OR(U23="",I23="",I23=0),"",U23*10000000/I23) | Y23: Non-SEZ office. Exit cap 8.00%, WACC 11.75%. Occ 61.5%/committed 72.3%. Market/marginal office rent INR60/psf/mo. Land ~6 ac freehold. chunk b
A24: Mindspace | B24: Mindspace Business Parks Private Limited | C24: Mindspace Airoli East | D24: Office | E24: Navi Mumbai | F24: Thane-Belapur Road | G24: Thane-Belapur Road (Airoli) | H24: Plot No.3, Kalwa Trans Thane Creek Ind. Area, Mindspace, Opp. Airoli Station, Airoli, Navi Mumbai 400708 | I24: 7400000 | J24: 7.4 | K24: 4.98 | L24: 0.83 | M24: 0.73 | N24: 69 | O24: 68.3 | P24: =IF(OR(N24="",O24="",O24=0),"",N24/O24-1) | Q24: 4.9 | R24: 48 | S24: 0.08 | T24: 0.12 | U24: 5802.395 | V24: =IF(OR(U24="",I24="",I24=0),"",U24*10000000/I24) | Y24: Grade A IT SEZ. Total 7.4 msf = 4.98 completed (occ/tenants shown) + 2.41 under-constr/future (B17 hotel+office, Bldg15; NIL occupancy). Exit cap 8.00%; WACC 11.75% completed, 13% UC. Completed occ 73.2%/committed 83.1%, 48 tenants. Land ~50.1 ac leasehold (MIDC 99yr). Also power distribution (see Energispace). chunk b
A25: Mindspace | B25: Gigaplex Estate Private Limited | C25: Mindspace Airoli West | D25: Office | E25: Navi Mumbai | F25: Thane-Belapur Road | G25: Thane-Belapur Road (Airoli) | H25: Mindspace Airoli West, Navi Mumbai, Maharashtra | I25: 6460000 | J25: 6.46 | K25: 5.41 | L25: 0.99 | M25: 0.97 | N25: 71 | O25: 67.2 | P25: =IF(OR(N25="",O25="",O25=0),"",N25/O25-1) | Q25: 9 | R25: 62 | S25: 0.08 | T25: 0.12 | U25: 6577 | V25: =IF(OR(U25="",I25="",I25=0),"",U25*10000000/I25) | Y25: IT SEZ w/ data-centre buildings. Total 6.46 msf incl UC data centres (B7,B9A,B11). Completed 5.41 msf occ 96.6%/committed 98.7%, 62 tenants. Exit cap 8.00% (completed; 8.25% terminal on some); WACC 11.75% completed/13% UC. Market office rent INR71/psf/mo. Land ~50 ac leasehold (MIDC 95yr). chunk b
A26: Mindspace | B26: Avocado Properties and Trading (India) Private Limited | C26: Paradigm Mindspace Malad | D26: Office | E26: Mumbai | F26: Malad | G26: Western Suburbs (Malad) | H26: Paradigm Mindspace Malad, Mumbai, Maharashtra | I26: 760000 | J26: 0.76 | K26: 0.76 | L26: 0.99 | M26: 0.99 | N26: 116 | O26: 108.5 | P26: =IF(OR(N26="",O26="",O26=0),"",N26/O26-1) | Q26: 3.1 | R26: 9 | S26: 0.08 | T26: 0.12 | U26: 1371.121 | V26: =IF(OR(U26="",I26="",I26=0),"",U26*10000000/I26) | Y26: Office. Exit cap 8.00%, WACC 11.75%. Occ 98.6%/committed 98.6%, 9 tenants. Market/marginal rent INR116/psf/mo, in-place INR108.5. WALE 3.1 yrs. Land ~4.2 ac freehold. chunk b
A27: Mindspace | B27: Avacado Properties and Trading (India) Private Limited | C27: The Square, BKC (Mumbai) | D27: Office | E27: Mumbai | F27: BKC | G27: BKC (SBD BKC) | H27: The Square, BKC, Mumbai, Maharashtra | I27: 150000 | J27: 0.15 | K27: 0.15 | L27: 1 | M27: 1 | N27: 318 | O27: 240 | P27: =IF(OR(N27="",O27="",O27=0),"",N27/O27-1) | R27: 1 | S27: 0.08 | T27: 0.12 | U27: 533.868 | V27: =IF(OR(U27="",I27="",I27=0),"",U27*10000000/I27) | Y27: BKC office, fully operational single-tenant. Exit cap ~7.5-7.75%, WACC 11.75%. Occ 100%/committed 100%, 1 office tenant. Market/marginal rent INR318, in-place INR240 psf/mo. MV INR5,338.68mn. Land ~0.9 ac. SPV Avacado Properties. chunk b
A28: Mindspace | B28: KRC (Ascent SPV) | C28: The Square / Ascent, Worli | D28: Office | E28: Mumbai | F28: Worli | G28: Worli (SBD Central) | H28: Ascent, Worli, Mumbai, Maharashtra | I28: 450000 | J28: 0.45 | K28: 0.45 | L28: 0.97 | M28: 0.96 | N28: 340 | O28: 306.3 | P28: =IF(OR(N28="",O28="",O28=0),"",N28/O28-1) | Q28: 7.9 | R28: 8 | S28: 0.08 | T28: 0.12 | U28: 2314.206 | V28: =IF(OR(U28="",I28="",I28=0),"",U28*10000000/I28) | Y28: Commercial Non-SEZ + 36 residential units to rent. Exit cap 7.50%, WACC 11.75%. Occ 95.5%/committed 96.7%, 8 office tenants. Market rent INR340, in-place INR306.3 psf/mo. Leasehold (perpetual). ~4.61 ac (22.45% undivided). chunk c
A29: Mindspace | B29: Mindspace Business Parks Private Limited | C29: Commerzone Yerwada (Pune) | D29: Office | E29: Pune | F29: Yerwada | G29: Yerwada (SBD East) | H29: Commerzone IT Park, Yerwada, Pune, Maharashtra | I29: 1790000 | J29: 1.79 | K29: 1.79 | L29: 0.96 | M29: 0.92 | N29: 82 | O29: 87.3 | P29: =IF(OR(N29="",O29="",O29=0),"",N29/O29-1) | Q29: 5.3 | R29: 19 | S29: 0.08 | T29: 0.12 | U29: 2235.438 | V29: =IF(OR(U29="",I29="",I29=0),"",U29*10000000/I29) | Y29: Office. Exit cap 8.00%, WACC 11.75%. Occ 91.8%/committed 96.3%, 19 tenants. Market/marginal office rent INR82, in-place INR87.3 psf/mo. Land ~25.7 ac freehold. chunk c
A30: Mindspace | B30: KRC Infrastructure and Projects Private Limited | C30: Gera Commerzone SEZ & IT Park (Kharadi, Pune) | D30: Office | E30: Pune | F30: Kharadi | G30: Kharadi (SBD East) | H30: Gera Commerzone SEZ and IT Park, Kharadi, Pune, Maharashtra | I30: 3000000 | J30: 3 | K30: 3 | L30: 1 | M30: 1 | N30: 90 | O30: 85.4 | P30: =IF(OR(N30="",O30="",O30=0),"",N30/O30-1) | Q30: 7.2 | R30: 28 | S30: 0.08 | T30: 0.12 | U30: 5311.9 | V30: =IF(OR(U30="",I30="",I30=0),"",U30*10000000/I30) | Y30: SEZ IT. Exit cap 7.75%, WACC 11.75% completed/13% UC. Occ 100%/100%, 28 tenants. Market office rent INR90, in-place INR85.4 psf/mo. Land ~26 ac freehold. chunk c
A31: Mindspace | B31: Mindspace Business Parks Private Limited | C31: The Square, Nagar Road (Pune) | D31: Office | E31: Pune | F31: Nagar Road | G31: Nagar Road (SBD East) | H31: The Square, Nagar Road, Pune, Maharashtra | I31: 780000 | J31: 0.78 | K31: 0.78 | L31: 1 | M31: 1 | N31: 85 | O31: 85.3 | P31: =IF(OR(N31="",O31="",O31=0),"",N31/O31-1) | Q31: 2.4 | R31: 4 | S31: 0.08 | T31: 0.12 | U31: 1055.141 | V31: =IF(OR(U31="",I31="",I31=0),"",U31*10000000/I31) | Y31: Office. Exit cap 8.00%, WACC 11.75%. Occ 100%/100%, 4 tenants. Market office rent INR85, in-place INR85.3 psf/mo. Land ~10.1 ac freehold. chunk c
A32: Mindspace | B32: Pramaan Properties Private Limited | C32: Pune IT Building, Kalyani Nagar | D32: Office | E32: Pune | F32: Kalyani Nagar | G32: Kalyani Nagar (SBD East) | H32: Pune IT Building (B8), Kalyani Nagar, Pune, Maharashtra | I32: 110000 | J32: 0.11 | K32: 0.11 | L32: 0.94 | M32: 0.88 | N32: 84 | O32: 86.2 | P32: =IF(OR(N32="",O32="",O32=0),"",N32/O32-1) | Q32: 6.34 | R32: 1 | S32: 0.08 | T32: 0.12 | U32: 148.151 | V32: =IF(OR(U32="",I32="",I32=0),"",U32*10000000/I32) | Y32: Single office building B8. Exit cap office 8.00%, WACC 11.75%. Occ 88.1%/committed 94.2%, 1 tenant. Market office rent INR84 (amenity INR65), in-place INR86.2 psf/mo. Land ~0.67 ac (39.96% undivided share) freehold. chunk d
A33: Mindspace | B33: Horizonview Properties Private Limited | C33: Commerzone Porur (Chennai) | D33: Office | E33: Chennai | F33: Porur | G33: Porur (SBD Southwest) | H33: Commerzone, Porur, Chennai, Tamil Nadu | I33: 1150000 | J33: 1.15 | K33: 1.15 | L33: 1 | M33: 1 | N33: 72 | O33: 65.7 | P33: =IF(OR(N33="",O33="",O33=0),"",N33/O33-1) | R33: 16 | S33: 0.08 | T33: 0.12 | U33: 1333.474 | V33: =IF(OR(U33="",I33="",I33=0),"",U33*10000000/I33) | Y33: Office. Exit cap 7.75%, WACC 11.75%. Occ 99.5%/committed 100%, 16 tenants. Market/marginal office rent INR72, in-place INR65.7 psf/mo. Land ~6.13 ac freehold. WALE not cleanly captured. chunk d
A34: Mindspace | B34: Sundew Real Estate Private Limited | C34: The Square, Avenue 98 (BKC Annex) | D34: Office | E34: Mumbai | F34: BKC-Annex | G34: BKC-Annex (SBD BKC) | H34: The Square, Avenue 98 (BKC Annex), Mumbai, Maharashtra | I34: 220000 | J34: 0.22 | K34: 0.16 | L34: 1 | M34: 1 | N34: 250 | O34: 197.1 | P34: =IF(OR(N34="",O34="",O34=0),"",N34/O34-1) | R34: 1 | S34: 0.08 | T34: 0.12 | U34: 756.9 | V34: =IF(OR(U34="",I34="",I34=0),"",U34*10000000/I34) | Y34: Commercial Non-SEZ. Leasable 0.22 msf, completed ~0.16 msf. Exit cap 7.50%, WACC 11.75%. Occ 100%/100%, 1 office tenant. Market rent INR250, in-place INR197.1 psf/mo. Land ~1.08 ac freehold. chunk d
A35: Brookfield | B35: Candor Kolkata One Hi-Tech Structures Private Limited | C35: Candor Techspace G2 | D35: Office | E35: Gurugram | F35: Dundahera | G35: Old Delhi-Gurugram Road, Dundahera (Gurugram, established office/residential/retail micro-market; near DLF Cyber City) | H35: Candor Techspace, Dundahera, Gurugram, Haryana | I35: 4183449 | J35: 4.18 | K35: 4.08 | L35: 0.83 | N35: 90 | O35: 88 | P35: =IF(OR(N35="",O35="",O35=0),"",N35/O35-1) | Q35: 8.1 | S35: 0.08 | T35: 0.12 | U35: 4811.2 | V35: =IF(OR(U35="",I35="",I35=0),"",U35*10000000/I35) | Y35: Completed leasable 4,083,525 sqft (13 bldgs, 83.34% committed occ) + future dev 99,924 sqft. WACC operational 11.50%, WACC under-construction/future dev 12.75% (discount_rate shown=12 rounded from 12.75 UC; operational WACC 11.5). REIT share 100% via Candor SPV; SPV entitled to 72% of gross revenue via JDA with Gurgaon Infospace Ltd (GIL owns land, gets 28%); economic interest in asset 72% (deck). Gross acq price K1+G2 = Rs 62.3 Bn. Completed MV 47,575mn + future dev 537mn = 48,112mn. Source val report pp.19-22; deck p.14 (Investor Pres FY26).
A36: Brookfield | B36: Seaview Developers Private Limited | C36: Candor Techspace N1 | D36: Office | E36: Noida | F36: Sector 62 (Noida) | G36: Sector 62, Noida (institutional sector, NCR) | H36: Plot no. B2, Sector 62, Noida, Uttar Pradesh | J36: 2.88 | K36: 2.02 | L36: 0.98 | N36: 72 | O36: 64 | P36: =IF(OR(N36="",O36="",O36=0),"",N36/O36-1) | Q36: 7.8 | S36: 0.08 | T36: 0.12 | U36: 2948.5 | V36: =IF(OR(U36="",I36="",I36=0),"",U36*10000000/I36) | Y36: Completed 20,23,237 sqft (7 bldgs, 97.96% committed occ) + future dev 0.86 msf. REIT share 100%. WACC operational 11.50%, UC 12.75%. Completed MV 26,026mn + future dev 3,459mn = 29,485mn. Source val report pp.23-26; deck p.14.
A37: Brookfield | B37: Festus Properties Private Limited | C37: Candor Techspace N2 | D37: Office | E37: Noida | F37: Sector 135 (Noida) | G37: Sector 135, Noida-Greater Noida Expressway micro-market | H37: Plot No. 20, 21, Sector 135, Noida, Uttar Pradesh | J37: 4.69 | K37: 3.92 | L37: 0.94 | N37: 70 | O37: 64 | P37: =IF(OR(N37="",O37="",O37=0),"",N37/O37-1) | Q37: 6.9 | S37: 0.08 | T37: 0.12 | U37: 4941 | V37: =IF(OR(U37="",I37="",I37=0),"",U37*10000000/I37) | Y37: Completed 39,15,881 sqft (14 bldgs, 93.52% committed occ) + future dev 0.77 msf. REIT share 100%. Achievable mkt rent: 70 SEZ office / 57 non-SEZ / 60 mixed-use retail; inplace(current effective) 64. WACC operational 11.50%, UC 12.75%. Completed MV 47,064mn + future dev 2,346mn = 49,410mn. Source val report pp.27-30; deck p.14.
A38: Brookfield | B38: Shantiniketan Properties Private Limited | C38: Candor Techspace K1 | D38: Office | E38: Kolkata | F38: New Town (Rajarhat) | G38: New Town, Rajarhat, Kolkata (established office micro-market; ~1.5km from CBD metro) | H38: Plot No. 1, DH Block, New Town, Rajarhat, Kolkata, West Bengal | J38: 5.89 | K38: 3.2 | L38: 0.99 | N38: 55 | O38: 49 | P38: =IF(OR(N38="",O38="",O38=0),"",N38/O38-1) | Q38: 8.9 | S38: 0.085 | T38: 0.12 | U38: 3621 | V38: =IF(OR(U38="",I38="",I38=0),"",U38*10000000/I38) | Y38: Completed 32,01,857 sqft (12 bldgs, 98.82% committed occ) + under construction 0.58 msf + future dev 2.11 msf. REIT share 100%. Achievable mkt rent 55 SEZ office /57 non-SEZ /60 mixed-use retail; inplace 49. Cap rate 8.50%. WACC operational 11.50%, UC 12.75%. MV: completed 29,479mn + UC 2,430mn + future dev 4,301mn = 36,210mn. Gross acq price K1+G2=Rs62.3Bn. Source val report pp.31-35; deck p.14.
A39: Brookfield | B39: Festus Properties Private Limited | C39: Kensington (A & B) | D39: Office | E39: Mumbai | F39: Powai / Andheri | G39: Andheri & Powai micro-market, MMR (only private IT/ITeS SEZ in Mumbai excl. Thane/Navi Mumbai) | H39: Hiranandani Business Park, CTS No. 28A, Powai, Mumbai 400076, Maharashtra | I39: 1619079 | J39: 1.61 | K39: 1.61 | L39: 0.96 | N39: 160 | O39: 136 | P39: =IF(OR(N39="",O39="",O39=0),"",N39/O39-1) | Q39: 9.1 | S39: 0.08 | T39: 0.12 | U39: 3198.1 | V39: =IF(OR(U39="",I39="",I39=0),"",U39*10000000/I39) | Y39: Single bldg two wings, 1,619,079 sqft, 95.61% committed occ (val rpt) / 96% (deck). REIT share 100%. Deck groups Kensington under 'Downtown Powai - SEZ' (100% economic interest). Property tax entity: Festus Properties Pvt Ltd (val rpt). Achievable mkt rent 160 IT SEZ /175 IT; inplace(current effective) 136. Cap rate 8.00%, WACC operational 11.50%. Major tenants: TCS, L&T, GE Oil & Gas, Ergo Technology, Nomura, Aptia, RXO. Gross acq price Rs22.9Bn. MV 31,981mn. Source val report pp.36-39; deck p.14.
A40: Brookfield | B40: Candor Gurgaon One Realty Projects Private Limited | C40: Candor Techspace G1 | D40: Office | E40: Gurugram | F40: Sector 48 (Gurugram) | G40: Sector 48, Gurugram (Village Tikri), Haryana | H40: Village Tikri, Sector 48, Gurugram, Haryana | J40: 3.89 | K40: 3.79 | L40: 0.89 | N40: 88 | O40: 83 | P40: =IF(OR(N40="",O40="",O40=0),"",N40/O40-1) | Q40: 6.3 | S40: 0.08 | T40: 0.12 | U40: 6048.9 | V40: =IF(OR(U40="",I40="",I40=0),"",U40*10000000/I40) | Y40: JV / North Commercial Portfolio - equity-accounted; REIT economic interest 50% (deck). Val report MV of financial interest is 100% asset value 60,489mn (completed 59,924mn + future dev 565mn); 12 completed bldgs, 88.67% committed occ (val rpt)/89% (deck). Held via North Commercial Portfolio Holding Entity (BIRET 50% / GIC 50%). WACC operational 11.50%, UC 12.75%. Source val report pp.40-43; deck p.14, p.38.
...

Sheet Pricing by Area
A1: City | B1: Type | C1: # Assets | D1: Leasable (msf) | E1: Market value (INR cr) | F1: Avg value/sqft (INR) | G1: Avg market rent | H1: Avg in-place rent | I1: Avg reversion | J1: Avg cap rate
A2: Ahmedabad | B2: Retail | C2: =COUNTIFS('Asset Register'!$E$2:$E$109,$A2,'Asset Register'!$D$2:$D$109,$B2) | D2: =SUMIFS('Asset Register'!$J$2:$J$109,'Asset Register'!$E$2:$E$109,$A2,'Asset Register'!$D$2:$D$109,$B2) | E2: =SUMIFS('Asset Register'!$U$2:$U$109,'Asset Register'!$E$2:$E$109,$A2,'Asset Register'!$D$2:$D$109,$B2) | F2: =IFERROR(SUMIFS('Asset Register'!$U$2:$U$109,'Asset Register'!$E$2:$E$109,$A2,'Asset Register'!$D$2:$D$109,$B2)*10000000/SUMIFS('Asset Register'!$I$2:$I$109,'Asset Register'!$E$2:$E$109,$A2,'Asset Register'!$D$2:$D$109,$B2),"") | G2: =IFERROR(AVERAGEIFS('Asset Register'!$N$2:$N$109,'Asset Register'!$E$2:$E$109,$A2,'Asset Register'!$D$2:$D$109,$B2),"") | H2: =IFERROR(AVERAGEIFS('Asset Register'!$O$2:$O$109,'Asset Register'!$E$2:$E$109,$A2,'Asset Register'!$D$2:$D$109,$B2),"") | I2: =IFERROR(AVERAGEIFS('Asset Register'!$P$2:$P$109,'Asset Register'!$E$2:$E$109,$A2,'Asset Register'!$D$2:$D$109,$B2),"") | J2: =IFERROR(AVERAGEIFS('Asset Register'!$S$2:$S$109,'Asset Register'!$E$2:$E$109,$A2,'Asset Register'!$D$2:$D$109,$B2),"")
A3: Amritsar | B3: Retail | C3: =COUNTIFS('Asset Register'!$E$2:$E$109,$A3,'Asset Register'!$D$2:$D$109,$B3) | D3: =SUMIFS('Asset Register'!$J$2:$J$109,'Asset Register'!$E$2:$E$109,$A3,'Asset Register'!$D$2:$D$109,$B3) | E3: =SUMIFS('Asset Register'!$U$2:$U$109,'Asset Register'!$E$2:$E$109,$A3,'Asset Register'!$D$2:$D$109,$B3) | F3: =IFERROR(SUMIFS('Asset Register'!$U$2:$U$109,'Asset Register'!$E$2:$E$109,$A3,'Asset Register'!$D$2:$D$109,$B3)*10000000/SUMIFS('Asset Register'!$I$2:$I$109,'Asset Register'!$E$2:$E$109,$A3,'Asset Register'!$D$2:$D$109,$B3),"") | G3: =IFERROR(AVERAGEIFS('Asset Register'!$N$2:$N$109,'Asset Register'!$E$2:$E$109,$A3,'Asset Register'!$D$2:$D$109,$B3),"") | H3: =IFERROR(AVERAGEIFS('Asset Register'!$O$2:$O$109,'Asset Register'!$E$2:$E$109,$A3,'Asset Register'!$D$2:$D$109,$B3),"") | I3: =IFERROR(AVERAGEIFS('Asset Register'!$P$2:$P$109,'Asset Register'!$E$2:$E$109,$A3,'Asset Register'!$D$2:$D$109,$B3),"") | J3: =IFERROR(AVERAGEIFS('Asset Register'!$S$2:$S$109,'Asset Register'!$E$2:$E$109,$A3,'Asset Register'!$D$2:$D$109,$B3),"")
A4: Bellary District, Karnataka | B4: Other | C4: =COUNTIFS('Asset Register'!$E$2:$E$109,$A4,'Asset Register'!$D$2:$D$109,$B4) | D4: =SUMIFS('Asset Register'!$J$2:$J$109,'Asset Register'!$E$2:$E$109,$A4,'Asset Register'!$D$2:$D$109,$B4) | E4: =SUMIFS('Asset Register'!$U$2:$U$109,'Asset Register'!$E$2:$E$109,$A4,'Asset Register'!$D$2:$D$109,$B4) | F4: =IFERROR(SUMIFS('Asset Register'!$U$2:$U$109,'Asset Register'!$E$2:$E$109,$A4,'Asset Register'!$D$2:$D$109,$B4)*10000000/SUMIFS('Asset Register'!$I$2:$I$109,'Asset Register'!$E$2:$E$109,$A4,'Asset Register'!$D$2:$D$109,$B4),"") | G4: =IFERROR(AVERAGEIFS('Asset Register'!$N$2:$N$109,'Asset Register'!$E$2:$E$109,$A4,'Asset Register'!$D$2:$D$109,$B4),"") | H4: =IFERROR(AVERAGEIFS('Asset Register'!$O$2:$O$109,'Asset Register'!$E$2:$E$109,$A4,'Asset Register'!$D$2:$D$109,$B4),"") | I4: =IFERROR(AVERAGEIFS('Asset Register'!$P$2:$P$109,'Asset Register'!$E$2:$E$109,$A4,'Asset Register'!$D$2:$D$109,$B4),"") | J4: =IFERROR(AVERAGEIFS('Asset Register'!$S$2:$S$109,'Asset Register'!$E$2:$E$109,$A4,'Asset Register'!$D$2:$D$109,$B4),"")
A5: Bengaluru | B5: Hotel | C5: =COUNTIFS('Asset Register'!$E$2:$E$109,$A5,'Asset Register'!$D$2:$D$109,$B5) | D5: =SUMIFS('Asset Register'!$J$2:$J$109,'Asset Register'!$E$2:$E$109,$A5,'Asset Register'!$D$2:$D$109,$B5) | E5: =SUMIFS('Asset Register'!$U$2:$U$109,'Asset Register'!$E$2:$E$109,$A5,'Asset Register'!$D$2:$D$109,$B5) | F5: =IFERROR(SUMIFS('Asset Register'!$U$2:$U$109,'Asset Register'!$E$2:$E$109,$A5,'Asset Register'!$D$2:$D$109,$B5)*10000000/SUMIFS('Asset Register'!$I$2:$I$109,'Asset Register'!$E$2:$E$109,$A5,'Asset Register'!$D$2:$D$109,$B5),"") | G5: =IFERROR(AVERAGEIFS('Asset Register'!$N$2:$N$109,'Asset Register'!$E$2:$E$109,$A5,'Asset Register'!$D$2:$D$109,$B5),"") | H5: =IFERROR(AVERAGEIFS('Asset Register'!$O$2:$O$109,'Asset Register'!$E$2:$E$109,$A5,'Asset Register'!$D$2:$D$109,$B5),"") | I5: =IFERROR(AVERAGEIFS('Asset Register'!$P$2:$P$109,'Asset Register'!$E$2:$E$109,$A5,'Asset Register'!$D$2:$D$109,$B5),"") | J5: =IFERROR(AVERAGEIFS('Asset Register'!$S$2:$S$109,'Asset Register'!$E$2:$E$109,$A5,'Asset Register'!$D$2:$D$109,$B5),"")
A6: Bengaluru | B6: Office | C6: =COUNTIFS('Asset Register'!$E$2:$E$109,$A6,'Asset Register'!$D$2:$D$109,$B6) | D6: =SUMIFS('Asset Register'!$J$2:$J$109,'Asset Register'!$E$2:$E$109,$A6,'Asset Register'!$D$2:$D$109,$B6) | E6: =SUMIFS('Asset Register'!$U$2:$U$109,'Asset Register'!$E$2:$E$109,$A6,'Asset Register'!$D$2:$D$109,$B6) | F6: =IFERROR(SUMIFS('Asset Register'!$U$2:$U$109,'Asset Register'!$E$2:$E$109,$A6,'Asset Register'!$D$2:$D$109,$B6)*10000000/SUMIFS('Asset Register'!$I$2:$I$109,'Asset Register'!$E$2:$E$109,$A6,'Asset Register'!$D$2:$D$109,$B6),"") | G6: =IFERROR(AVERAGEIFS('Asset Register'!$N$2:$N$109,'Asset Register'!$E$2:$E$109,$A6,'Asset Register'!$D$2:$D$109,$B6),"") | H6: =IFERROR(AVERAGEIFS('Asset Register'!$O$2:$O$109,'Asset Register'!$E$2:$E$109,$A6,'Asset Register'!$D$2:$D$109,$B6),"") | I6: =IFERROR(AVERAGEIFS('Asset Register'!$P$2:$P$109,'Asset Register'!$E$2:$E$109,$A6,'Asset Register'!$D$2:$D$109,$B6),"") | J6: =IFERROR(AVERAGEIFS('Asset Register'!$S$2:$S$109,'Asset Register'!$E$2:$E$109,$A6,'Asset Register'!$D$2:$D$109,$B6),"")
A7: Bengaluru | B7: Retail | C7: =COUNTIFS('Asset Register'!$E$2:$E$109,$A7,'Asset Register'!$D$2:$D$109,$B7) | D7: =SUMIFS('Asset Register'!$J$2:$J$109,'Asset Register'!$E$2:$E$109,$A7,'Asset Register'!$D$2:$D$109,$B7) | E7: =SUMIFS('Asset Register'!$U$2:$U$109,'Asset Register'!$E$2:$E$109,$A7,'Asset Register'!$D$2:$D$109,$B7) | F7: =IFERROR(SUMIFS('Asset Register'!$U$2:$U$109,'Asset Register'!$E$2:$E$109,$A7,'Asset Register'!$D$2:$D$109,$B7)*10000000/SUMIFS('Asset Register'!$I$2:$I$109,'Asset Register'!$E$2:$E$109,$A7,'Asset Register'!$D$2:$D$109,$B7),"") | G7: =IFERROR(AVERAGEIFS('Asset Register'!$N$2:$N$109,'Asset Register'!$E$2:$E$109,$A7,'Asset Register'!$D$2:$D$109,$B7),"") | H7: =IFERROR(AVERAGEIFS('Asset Register'!$O$2:$O$109,'Asset Register'!$E$2:$E$109,$A7,'Asset Register'!$D$2:$D$109,$B7),"") | I7: =IFERROR(AVERAGEIFS('Asset Register'!$P$2:$P$109,'Asset Register'!$E$2:$E$109,$A7,'Asset Register'!$D$2:$D$109,$B7),"") | J7: =IFERROR(AVERAGEIFS('Asset Register'!$S$2:$S$109,'Asset Register'!$E$2:$E$109,$A7,'Asset Register'!$D$2:$D$109,$B7),"")
A8: Bhubaneswar | B8: Retail | C8: =COUNTIFS('Asset Register'!$E$2:$E$109,$A8,'Asset Register'!$D$2:$D$109,$B8) | D8: =SUMIFS('Asset Register'!$J$2:$J$109,'Asset Register'!$E$2:$E$109,$A8,'Asset Register'!$D$2:$D$109,$B8) | E8: =SUMIFS('Asset Register'!$U$2:$U$109,'Asset Register'!$E$2:$E$109,$A8,'Asset Register'!$D$2:$D$109,$B8) | F8: =IFERROR(SUMIFS('Asset Register'!$U$2:$U$109,'Asset Register'!$E$2:$E$109,$A8,'Asset Register'!$D$2:$D$109,$B8)*10000000/SUMIFS('Asset Register'!$I$2:$I$109,'Asset Register'!$E$2:$E$109,$A8,'Asset Register'!$D$2:$D$109,$B8),"") | G8: =IFERROR(AVERAGEIFS('Asset Register'!$N$2:$N$109,'Asset Register'!$E$2:$E$109,$A8,'Asset Register'!$D$2:$D$109,$B8),"") | H8: =IFERROR(AVERAGEIFS('Asset Register'!$O$2:$O$109,'Asset Register'!$E$2:$E$109,$A8,'Asset Register'!$D$2:$D$109,$B8),"") | I8: =IFERROR(AVERAGEIFS('Asset Register'!$P$2:$P$109,'Asset Register'!$E$2:$E$109,$A8,'Asset Register'!$D$2:$D$109,$B8),"") | J8: =IFERROR(AVERAGEIFS('Asset Register'!$S$2:$S$109,'Asset Register'!$E$2:$E$109,$A8,'Asset Register'!$D$2:$D$109,$B8),"")
A9: Chandigarh | B9: Retail | C9: =COUNTIFS('Asset Register'!$E$2:$E$109,$A9,'Asset Register'!$D$2:$D$109,$B9) | D9: =SUMIFS('Asset Register'!$J$2:$J$109,'Asset Register'!$E$2:$E$109,$A9,'Asset Register'!$D$2:$D$109,$B9) | E9: =SUMIFS('Asset Register'!$U$2:$U$109,'Asset Register'!$E$2:$E$109,$A9,'Asset Register'!$D$2:$D$109,$B9) | F9: =IFERROR(SUMIFS('Asset Register'!$U$2:$U$109,'Asset Register'!$E$2:$E$109,$A9,'Asset Register'!$D$2:$D$109,$B9)*10000000/SUMIFS('Asset Register'!$I$2:$I$109,'Asset Register'!$E$2:$E$109,$A9,'Asset Register'!$D$2:$D$109,$B9),"") | G9: =IFERROR(AVERAGEIFS('Asset Register'!$N$2:$N$109,'Asset Register'!$E$2:$E$109,$A9,'Asset Register'!$D$2:$D$109,$B9),"") | H9: =IFERROR(AVERAGEIFS('Asset Register'!$O$2:$O$109,'Asset Register'!$E$2:$E$109,$A9,'Asset Register'!$D$2:$D$109,$B9),"") | I9: =IFERROR(AVERAGEIFS('Asset Register'!$P$2:$P$109,'Asset Register'!$E$2:$E$109,$A9,'Asset Register'!$D$2:$D$109,$B9),"") | J9: =IFERROR(AVERAGEIFS('Asset Register'!$S$2:$S$109,'Asset Register'!$E$2:$E$109,$A9,'Asset Register'!$D$2:$D$109,$B9),"")
A10: Chennai | B10: Office | C10: =COUNTIFS('Asset Register'!$E$2:$E$109,$A10,'Asset Register'!$D$2:$D$109,$B10) | D10: =SUMIFS('Asset Register'!$J$2:$J$109,'Asset Register'!$E$2:$E$109,$A10,'Asset Register'!$D$2:$D$109,$B10) | E10: =SUMIFS('Asset Register'!$U$2:$U$109,'Asset Register'!$E$2:$E$109,$A10,'Asset Register'!$D$2:$D$109,$B10) | F10: =IFERROR(SUMIFS('Asset Register'!$U$2:$U$109,'Asset Register'!$E$2:$E$109,$A10,'Asset Register'!$D$2:$D$109,$B10)*10000000/SUMIFS('Asset Register'!$I$2:$I$109,'Asset Register'!$E$2:$E$109,$A10,'Asset Register'!$D$2:$D$109,$B10),"") | G10: =IFERROR(AVERAGEIFS('Asset Register'!$N$2:$N$109,'Asset Register'!$E$2:$E$109,$A10,'Asset Register'!$D$2:$D$109,$B10),"") | H10: =IFERROR(AVERAGEIFS('Asset Register'!$O$2:$O$109,'Asset Register'!$E$2:$E$109,$A10,'Asset Register'!$D$2:$D$109,$B10),"") | I10: =IFERROR(AVERAGEIFS('Asset Register'!$P$2:$P$109,'Asset Register'!$E$2:$E$109,$A10,'Asset Register'!$D$2:$D$109,$B10),"") | J10: =IFERROR(AVERAGEIFS('Asset Register'!$S$2:$S$109,'Asset Register'!$E$2:$E$109,$A10,'Asset Register'!$D$2:$D$109,$B10),"")
A11: Chennai | B11: Retail | C11: =COUNTIFS('Asset Register'!$E$2:$E$109,$A11,'Asset Register'!$D$2:$D$109,$B11) | D11: =SUMIFS('Asset Register'!$J$2:$J$109,'Asset Register'!$E$2:$E$109,$A11,'Asset Register'!$D$2:$D$109,$B11) | E11: =SUMIFS('Asset Register'!$U$2:$U$109,'Asset Register'!$E$2:$E$109,$A11,'Asset Register'!$D$2:$D$109,$B11) | F11: =IFERROR(SUMIFS('Asset Register'!$U$2:$U$109,'Asset Register'!$E$2:$E$109,$A11,'Asset Register'!$D$2:$D$109,$B11)*10000000/SUMIFS('Asset Register'!$I$2:$I$109,'Asset Register'!$E$2:$E$109,$A11,'Asset Register'!$D$2:$D$109,$B11),"") | G11: =IFERROR(AVERAGEIFS('Asset Register'!$N$2:$N$109,'Asset Register'!$E$2:$E$109,$A11,'Asset Register'!$D$2:$D$109,$B11),"") | H11: =IFERROR(AVERAGEIFS('Asset Register'!$O$2:$O$109,'Asset Register'!$E$2:$E$109,$A11,'Asset Register'!$D$2:$D$109,$B11),"") | I11: =IFERROR(AVERAGEIFS('Asset Register'!$P$2:$P$109,'Asset Register'!$E$2:$E$109,$A11,'Asset Register'!$D$2:$D$109,$B11),"") | J11: =IFERROR(AVERAGEIFS('Asset Register'!$S$2:$S$109,'Asset Register'!$E$2:$E$109,$A11,'Asset Register'!$D$2:$D$109,$B11),"")
A12: Chitradurga, Karnataka | B12: Solar | C12: =COUNTIFS('Asset Register'!$E$2:$E$109,$A12,'Asset Register'!$D$2:$D$109,$B12) | D12: =SUMIFS('Asset Register'!$J$2:$J$109,'Asset Register'!$E$2:$E$109,$A12,'Asset Register'!$D$2:$D$109,$B12) | E12: =SUMIFS('Asset Register'!$U$2:$U$109,'Asset Register'!$E$2:$E$109,$A12,'Asset Register'!$D$2:$D$109,$B12) | F12: =IFERROR(SUMIFS('Asset Register'!$U$2:$U$109,'Asset Register'!$E$2:$E$109,$A12,'Asset Register'!$D$2:$D$109,$B12)*10000000/SUMIFS('Asset Register'!$I$2:$I$109,'Asset Register'!$E$2:$E$109,$A12,'Asset Register'!$D$2:$D$109,$B12),"") | G12: =IFERROR(AVERAGEIFS('Asset Register'!$N$2:$N$109,'Asset Register'!$E$2:$E$109,$A12,'Asset Register'!$D$2:$D$109,$B12),"") | H12: =IFERROR(AVERAGEIFS('Asset Register'!$O$2:$O$109,'Asset Register'!$E$2:$E$109,$A12,'Asset Register'!$D$2:$D$109,$B12),"") | I12: =IFERROR(AVERAGEIFS('Asset Register'!$P$2:$P$109,'Asset Register'!$E$2:$E$109,$A12,'Asset Register'!$D$2:$D$109,$B12),"") | J12: =IFERROR(AVERAGEIFS('Asset Register'!$S$2:$S$109,'Asset Register'!$E$2:$E$109,$A12,'Asset Register'!$D$2:$D$109,$B12),"")
A13: Dhule, Maharashtra | B13: Solar | C13: =COUNTIFS('Asset Register'!$E$2:$E$109,$A13,'Asset Register'!$D$2:$D$109,$B13) | D13: =SUMIFS('Asset Register'!$J$2:$J$109,'Asset Register'!$E$2:$E$109,$A13,'Asset Register'!$D$2:$D$109,$B13) | E13: =SUMIFS('Asset Register'!$U$2:$U$109,'Asset Register'!$E$2:$E$109,$A13,'Asset Register'!$D$2:$D$109,$B13) | F13: =IFERROR(SUMIFS('Asset Register'!$U$2:$U$109,'Asset Register'!$E$2:$E$109,$A13,'Asset Register'!$D$2:$D$109,$B13)*10000000/SUMIFS('Asset Register'!$I$2:$I$109,'Asset Register'!$E$2:$E$109,$A13,'Asset Register'!$D$2:$D$109,$B13),"") | G13: =IFERROR(AVERAGEIFS('Asset Register'!$N$2:$N$109,'Asset Register'!$E$2:$E$109,$A13,'Asset Register'!$D$2:$D$109,$B13),"") | H13: =IFERROR(AVERAGEIFS('Asset Register'!$O$2:$O$109,'Asset Register'!$E$2:$E$109,$A13,'Asset Register'!$D$2:$D$109,$B13),"") | I13: =IFERROR(AVERAGEIFS('Asset Register'!$P$2:$P$109,'Asset Register'!$E$2:$E$109,$A13,'Asset Register'!$D$2:$D$109,$B13),"") | J13: =IFERROR(AVERAGEIFS('Asset Register'!$S$2:$S$109,'Asset Register'!$E$2:$E$109,$A13,'Asset Register'!$D$2:$D$109,$B13),"")
... A34: Vijayapura | B34: Solar | C34: =COUNTIFS('Asset Register'!$E$2:$E$109,$A34,'Asset Register'!$D$2:$D$109,$B34) | D34: =SUMIFS('Asset Register'!$J$2:$J$109,'Asset Register'!$E$2:$E$109,$A34,'Asset Register'!$D$2:$D$109,$B34) | E34: =SUMIFS('Asset Register'!$U$2:$U$109,'Asset Register'!$E$2:$E$109,$A34,'Asset Register'!$D$2:$D$109,$B34) | F34: =IFERROR(SUMIFS('Asset Register'!$U$2:$U$109,'Asset Register'!$E$2:$E$109,$A34,'Asset Register'!$D$2:$D$109,$B34)*10000000/SUMIFS('Asset Register'!$I$2:$I$109,'Asset Register'!$E$2:$E$109,$A34,'Asset Register'!$D$2:$D$109,$B34),"") | G34: =IFERROR(AVERAGEIFS('Asset Register'!$N$2:$N$109,'Asset Register'!$E$2:$E$109,$A34,'Asset Register'!$D$2:$D$109,$B34),"") | H34: =IFERROR(AVERAGEIFS('Asset Register'!$O$2:$O$109,'Asset Register'!$E$2:$E$109,$A34,'Asset Register'!$D$2:$D$109,$B34),"") | I34: =IFERROR(AVERAGEIFS('Asset Register'!$P$2:$P$109,'Asset Register'!$E$2:$E$109,$A34,'Asset Register'!$D$2:$D$109,$B34),"") | J34: =IFERROR(AVERAGEIFS('Asset Register'!$S$2:$S$109,'Asset Register'!$E$2:$E$109,$A34,'Asset Register'!$D$2:$D$109,$B34),"")

Sheet By REIT
A1: REIT | B1: # Assets | C1: Leasable (msf) | D1: Portfolio value (INR cr) | E1: Avg value/sqft (INR) | F1: Avg market rent | G1: Avg in-place rent | H1: Avg cap rate
A2: Embassy | B2: =COUNTIFS('Asset Register'!$A$2:$A$109,$A2) | C2: =SUMIFS('Asset Register'!$J$2:$J$109,'Asset Register'!$A$2:$A$109,$A2) | D2: =SUMIFS('Asset Register'!$U$2:$U$109,'Asset Register'!$A$2:$A$109,$A2) | E2: =IFERROR(SUMIFS('Asset Register'!$U$2:$U$109,'Asset Register'!$A$2:$A$109,$A2)*10000000/SUMIFS('Asset Register'!$I$2:$I$109,'Asset Register'!$A$2:$A$109,$A2),"") | F2: =IFERROR(AVERAGEIFS('Asset Register'!$N$2:$N$109,'Asset Register'!$A$2:$A$109,$A2),"") | G2: =IFERROR(AVERAGEIFS('Asset Register'!$O$2:$O$109,'Asset Register'!$A$2:$A$109,$A2),"") | H2: =IFERROR(AVERAGEIFS('Asset Register'!$S$2:$S$109,'Asset Register'!$A$2:$A$109,$A2),"")
A3: Mindspace | B3: =COUNTIFS('Asset Register'!$A$2:$A$109,$A3) | C3: =SUMIFS('Asset Register'!$J$2:$J$109,'Asset Register'!$A$2:$A$109,$A3) | D3: =SUMIFS('Asset Register'!$U$2:$U$109,'Asset Register'!$A$2:$A$109,$A3) | E3: =IFERROR(SUMIFS('Asset Register'!$U$2:$U$109,'Asset Register'!$A$2:$A$109,$A3)*10000000/SUMIFS('Asset Register'!$I$2:$I$109,'Asset Register'!$A$2:$A$109,$A3),"") | F3: =IFERROR(AVERAGEIFS('Asset Register'!$N$2:$N$109,'Asset Register'!$A$2:$A$109,$A3),"") | G3: =IFERROR(AVERAGEIFS('Asset Register'!$O$2:$O$109,'Asset Register'!$A$2:$A$109,$A3),"") | H3: =IFERROR(AVERAGEIFS('Asset Register'!$S$2:$S$109,'Asset Register'!$A$2:$A$109,$A3),"")
A4: Brookfield | B4: =COUNTIFS('Asset Register'!$A$2:$A$109,$A4) | C4: =SUMIFS('Asset Register'!$J$2:$J$109,'Asset Register'!$A$2:$A$109,$A4) | D4: =SUMIFS('Asset Register'!$U$2:$U$109,'Asset Register'!$A$2:$A$109,$A4) | E4: =IFERROR(SUMIFS('Asset Register'!$U$2:$U$109,'Asset Register'!$A$2:$A$109,$A4)*10000000/SUMIFS('Asset Register'!$I$2:$I$109,'Asset Register'!$A$2:$A$109,$A4),"") | F4: =IFERROR(AVERAGEIFS('Asset Register'!$N$2:$N$109,'Asset Register'!$A$2:$A$109,$A4),"") | G4: =IFERROR(AVERAGEIFS('Asset Register'!$O$2:$O$109,'Asset Register'!$A$2:$A$109,$A4),"") | H4: =IFERROR(AVERAGEIFS('Asset Register'!$S$2:$S$109,'Asset Register'!$A$2:$A$109,$A4),"")
A5: Nexus | B5: =COUNTIFS('Asset Register'!$A$2:$A$109,$A5) | C5: =SUMIFS('Asset Register'!$J$2:$J$109,'Asset Register'!$A$2:$A$109,$A5) | D5: =SUMIFS('Asset Register'!$U$2:$U$109,'Asset Register'!$A$2:$A$109,$A5) | E5: =IFERROR(SUMIFS('Asset Register'!$U$2:$U$109,'Asset Register'!$A$2:$A$109,$A5)*10000000/SUMIFS('Asset Register'!$I$2:$I$109,'Asset Register'!$A$2:$A$109,$A5),"") | F5: =IFERROR(AVERAGEIFS('Asset Register'!$N$2:$N$109,'Asset Register'!$A$2:$A$109,$A5),"") | G5: =IFERROR(AVERAGEIFS('Asset Register'!$O$2:$O$109,'Asset Register'!$A$2:$A$109,$A5),"") | H5: =IFERROR(AVERAGEIFS('Asset Register'!$S$2:$S$109,'Asset Register'!$A$2:$A$109,$A5),"")
A6: KRT | B6: =COUNTIFS('Asset Register'!$A$2:$A$109,$A6) | C6: =SUMIFS('Asset Register'!$J$2:$J$109,'Asset Register'!$A$2:$A$109,$A6) | D6: =SUMIFS('Asset Register'!$U$2:$U$109,'Asset Register'!$A$2:$A$109,$A6) | E6: =IFERROR(SUMIFS('Asset Register'!$U$2:$U$109,'Asset Register'!$A$2:$A$109,$A6)*10000000/SUMIFS('Asset Register'!$I$2:$I$109,'Asset Register'!$A$2:$A$109,$A6),"") | F6: =IFERROR(AVERAGEIFS('Asset Register'!$N$2:$N$109,'Asset Register'!$A$2:$A$109,$A6),"") | G6: =IFERROR(AVERAGEIFS('Asset Register'!$O$2:$O$109,'Asset Register'!$A$2:$A$109,$A6),"") | H6: =IFERROR(AVERAGEIFS('Asset Register'!$S$2:$S$109,'Asset Register'!$A$2:$A$109,$A6),"")
A7: Bagmane | B7: =COUNTIFS('Asset Register'!$A$2:$A$109,$A7) | C7: =SUMIFS('Asset Register'!$J$2:$J$109,'Asset Register'!$A$2:$A$109,$A7) | D7: =SUMIFS('Asset Register'!$U$2:$U$109,'Asset Register'!$A$2:$A$109,$A7) | E7: =IFERROR(SUMIFS('Asset Register'!$U$2:$U$109,'Asset Register'!$A$2:$A$109,$A7)*10000000/SUMIFS('Asset Register'!$I$2:$I$109,'Asset Register'!$A$2:$A$109,$A7),"") | F7: =IFERROR(AVERAGEIFS('Asset Register'!$N$2:$N$109,'Asset Register'!$A$2:$A$109,$A7),"") | G7: =IFERROR(AVERAGEIFS('Asset Register'!$O$2:$O$109,'Asset Register'!$A$2:$A$109,$A7),"") | H7: =IFERROR(AVERAGEIFS('Asset Register'!$S$2:$S$109,'Asset Register'!$A$2:$A$109,$A7),"")
A8: TOTAL | B8: =SUM(B2:B7) | C8: =SUM(C2:C7) | D8: =SUM(D2:D7)

Sheet Embassy
A1: Embassy - Asset-level detail (valuation 31 Mar 2026; 16 assets)
A3: SPV / Holding entity | B3: Property / Asset | C3: Type | D3: City | E3: Locality / Area | F3: Micro-market (valuer) | G3: Address | H3: Leasable (sq ft) | I3: Leasable (msf) | J3: Completed (msf) | K3: Committed occ. | L3: In-place occ. | M3: Market rent /sqft/mo | N3: In-place rent /sqft/mo | O3: Rent reversion | P3: WALE (yrs) | Q3: Tenants | R3: Cap rate | S3: Discount rate | T3: Market value (INR cr) | U3: Value/sqft (INR) | V3: Mgmt fee (valuation DCF) | W3: Insurance (valuation DCF) | X3: Notes / source
A4: Manyata Promoters Private Limited (MPPL) | B4: Embassy Manyata | C4: Office | D4: Bengaluru | E4: Nagawara / Hebbal | F4: Peripheral North (Outer Ring Road / Hebbal stretch) | G4: Along Outer Ring Road, Nagawara, Bengaluru, Karnataka; land approx. 119.15 acres | H4: 17200000 | I4: 17.2 | J4: 14.6 | L4: 0.94 | M4: 105 | N4: 95 | O4: =IF(OR(M4="",N4="",N4=0),"",M4/N4-1) | P4: 8.8 | R4: 0.08 | S4: 0.12 | T4: 27868.9 | U4: =IF(OR(T4="",H4="",H4=0),"",T4*10000000/H4) | V4: Property Management Fees = 3% of Total Income (lease rentals, parking, fitout, other operating income) | W4: INR 0.3/sqft/mo; property tax & insurance escalated 3% p.a. | X4: Mixed-use: completed office 14.6 msf + UC/proposed office 2.6 msf + Hotel (5-star 266 keys, 3-star 353 keys). Value split: completed 242,591 + UC/proposed 17,026 + hotel 19,072. Cap rate 8% office/retail, 7.14% hospitality; discount rate 11.5% operational office, 12.75% UC, 11.90% hospitality (reported field uses office cap 8% / operational discount ~11.5-12.75, rounded to 12). Retail mkt rent 105, anchor 94.5. Blocks M3A/M3B on leasehold land from EPDPL. Source lines ~9433-10476, value summary L4237.
A5: Vikas Telecom Private Limited (VTPL) & Sarla Infrastructure Private Limited (SIPL) | B5: Embassy TechVillage | C5: Office | D5: Bengaluru | E5: Bellandur | F5: Outer Ring Road (Sarjapura-Marathahalli), Bellandur-Marathahalli | G5: Devarabeesanahalli Village & Kariyamanna Agrahara Village, Varthur Hobli, Bengaluru East Taluk, Karnataka; land approx. 84.05 acres under purview | H5: 9700000 | I5: 9.7 | J5: 9.2 | L5: 0.95 | M5: 105 | N5: 90 | O5: =IF(OR(M5="",N5="",N5=0),"",M5/N5-1) | P5: 9.5 | R5: 0.08 | S5: 0.12 | T5: 16624.6 | U5: =IF(OR(T5="",H5="",H5=0),"",T5*10000000/H5) | V5: Property Management Fees = 3% of Total Income | W5: INR 0.21/sqft/mo | X5: Mixed-use: completed office 9.2 msf + UC office 0.4 msf + 2 UC hotels (5-star 311 keys, 3-star 207 keys). Value split: completed 153,974 + UC/proposed 4,258 + hotel 8,014. Cap 8% office/retail, 7.14% hospitality; discount 11.5% operational, 12.75% UC office, 13.25% UC hotel. Retail mkt rent 90. SIPL portion (1.2 msf, Block 9) BTS to JP Morgan. Source lines ~10477-11428.
A6: GolfLinks Software Park Private Limited (GLSP, 50% JV) + Eleanor Realty Holdings India Private Limited (ERHIPL, Pinehurst 100%) | B6: Embassy GolfLinks (incl. Pinehurst) | C6: Office | D6: Bengaluru | E6: Domlur | F6: Suburban East (Intermediate Ring Road, near CBD) | G6: Challaghatta Village, Varthur Hobli, Mahadevapura, Bengaluru East Taluk 560071; land approx. 37.1 acres | H6: 3400000 | I6: 3.4 | J6: 3.4 | L6: 1 | M6: 170 | N6: 160 | O6: =IF(OR(M6="",N6="",N6=0),"",M6/N6-1) | P6: 10 | R6: 0.08 | S6: 0.12 | T6: 5129.8 | U6: =IF(OR(T6="",H6="",H6=0),"",T6*10000000/H6) | V6: Property Management Fees = 3% of Total Income (both GolfLinks and Pinehurst) | W6: GolfLinks INR 0.3/sqft/mo; Pinehurst INR 0.5/sqft/mo | X6: 100% property value = GolfLinks 84,937 + Pinehurst 8,829 = 93,766; REIT economic interest = 50% of GolfLinks + 100% Pinehurst = 51,298 (this is the share-of-total value shown in the portfolio summary). Cap 7.75% office/retail; discount 11.5% operational. Pinehurst (0.3 msf) acquired via 100% Eleanor Realty stake Q3 FY2026: mkt rent 180, in-place 167 (192 as of 1-Apr-2026). GolfLinks office mkt rent 170, in-place 160; retail mkt rent 55. cap_rate field records 7.75 rounded to 8. Source lines ~11429-12099; summary L4288.
A7: Quadron Business Park Private Limited (QBPL) | B7: Embassy One | C7: Office | D7: Bengaluru | E7: Bellary Road (Mekhri Circle) | F7: Peripheral North (between Hebbal and off-CBD) | G7: Embassy One, Bellary Road, Ganga Nagar, Bengaluru, Karnataka; land approx. 5.6 acres (3.2 acres under valuation scope) | H7: 300000 | I7: 0.3 | J7: 0.3 | L7: 1 | M7: 151 | N7: 151 | O7: =IF(OR(M7="",N7="",N7=0),"",M7/N7-1) | P7: 7.6 | R7: 0.08 | S7: 0.12 | T7: 1572 | U7: =IF(OR(T7="",H7="",H7=0),"",T7*10000000/H7) | V7: Property Management Fees = 3% of Total Income | W7: INR 0.4/sqft/mo | X7: Mixed-use: completed office 0.3 msf (Pinnacle tower) + Four Seasons hotel 230 keys (5-star). Value split: office 5,902 + hotel 9,818 = 15,720. Cap 7.75% office, 7.14% hospitality (recorded 8, rounded); discount 11.5% operational, 11.90% hospitality. Office mkt rent = in-place 151 (incl. car park). Residential apartments excluded. Vacancy provision 5%. SPV Quadron Business Park Pvt Ltd (same SPV that owns Embassy Quadron Pune). Source lines ~12100-12800.
A8: Embassy Construction Private Limited (ECPL) | B8: Embassy Business Hub | C8: Office | D8: Bengaluru | E8: Yelahanka | F8: Peripheral North / North Bengaluru (Yelahanka-Devanahalli) | G8: Sy. No. 25/2, 25/3 & 26, Venkatala Village, Bellary Road (NH-44), Yelahanka, Bengaluru North, Karnataka; JDA land approx. 13 acres | H8: 1400000 | I8: 1.4 | J8: 0.4 | M8: 69 | N8: 58 | O8: =IF(OR(M8="",N8="",N8=0),"",M8/N8-1) | Q8: 1 | R8: 0.08 | S8: 0.12 | T8: 722.4 | U8: =IF(OR(T8="",H8="",H8=0),"",T8*10000000/H8) | V8: Property Management Fees = 3% of Total Income | W8: INR 0.25/sqft/mo | X8: REIT share (developer share under JDA) approx. 1.4 msf: Phase I completed 0.4 msf (single tenant Philips India, lease to Nov 2038) + Phase II UC 1.0 msf (completion FY2028). Value split: Phase I 4,652 + Phase II UC 2,572 = 7,224. Cap 8%; discount 11.5% Phase I operational, 12.75% Phase II UC. SPV named from consolidated AR/FS (ECPL) - valuation report showed only JDA ownership, no explicit Entity line. Phase II pending dev cost INR 6,569 Mn. Source lines ~12802-13413; AR L1275/7021.
A9: Indian Express Newspapers (Mumbai) Private Limited (IENMPL) | B9: Express Towers | C9: Office | D9: Mumbai | E9: Nariman Point | F9: South Mumbai CBD (Nariman Point) | G9: Plot No. 236, Block III of Backbay Reclamation Estate, Barrister Rajni Patel Marg, Nariman Point, Mumbai; land approx. 1.5 acres (freehold) | H9: 500000 | I9: 0.5 | J9: 0.5 | L9: 1 | M9: 350 | N9: 296 | O9: =IF(OR(M9="",N9="",N9=0),"",M9/N9-1) | P9: 4 | R9: 0.08 | S9: 0.12 | T9: 2449.9 | U9: =IF(OR(T9="",H9="",H9=0),"",T9*10000000/H9) | V9: Property Management Fees = 3% of Total Income | W9: INR 0.4/sqft/mo | X9: Completed office 0.5 msf (= total). Cap 7.5% (recorded 8, rounded); discount 11.5% operational. Office mkt rent revised 300->350; in-place 296. Age ~56 yrs, LEED Platinum. Acquisition price INR 18,385 Mn (related party). Source lines ~13414-13934.
