Workbook

Sheet Comparison
A1: Indian Listed REITs - Comparison Dashboard
A2: Year: | B2: FY2026 | C2: Pick any year (FY2019-FY2026). Consolidated basis. Figures pull live from each REIT sheet (INR crore).
A4: Metric | B4: Unit | C4: Embassy | D4: Mindspace | E4: Brookfield | F4: Nexus (Retail) | G4: Knowledge / KRT | H4: Bagmane*
A5: Revenue from Operations | B5: INR cr | C5: =IFERROR(INDEX(Embassy!$C:$J,9,MATCH($B$2,Embassy!$C$7:$J$7,0)),"") | D5: =IFERROR(INDEX(Mindspace!$C:$J,9,MATCH($B$2,Mindspace!$C$7:$J$7,0)),"") | E5: =IFERROR(INDEX(Brookfield!$C:$J,9,MATCH($B$2,Brookfield!$C$7:$J$7,0)),"") | F5: =IFERROR(INDEX(Nexus!$C:$J,9,MATCH($B$2,Nexus!$C$7:$J$7,0)),"") | G5: =IFERROR(INDEX('Knowledge (KRT)'!$C:$J,9,MATCH($B$2,'Knowledge (KRT)'!$C$7:$J$7,0)),"") | H5: =IFERROR(INDEX(Bagmane!$C:$J,9,MATCH($B$2,Bagmane!$C$7:$J$7,0)),"")
A6: Net Operating Income (NOI) | B6: INR cr | C6: =IFERROR(INDEX(Embassy!$C:$J,13,MATCH($B$2,Embassy!$C$7:$J$7,0)),"") | D6: =IFERROR(INDEX(Mindspace!$C:$J,13,MATCH($B$2,Mindspace!$C$7:$J$7,0)),"") | E6: =IFERROR(INDEX(Brookfield!$C:$J,13,MATCH($B$2,Brookfield!$C$7:$J$7,0)),"") | F6: =IFERROR(INDEX(Nexus!$C:$J,13,MATCH($B$2,Nexus!$C$7:$J$7,0)),"") | G6: =IFERROR(INDEX('Knowledge (KRT)'!$C:$J,13,MATCH($B$2,'Knowledge (KRT)'!$C$7:$J$7,0)),"") | H6: =IFERROR(INDEX(Bagmane!$C:$J,13,MATCH($B$2,Bagmane!$C$7:$J$7,0)),"")
A7: NOI Margin | B7: % | C7: =IFERROR(INDEX(Embassy!$C:$J,14,MATCH($B$2,Embassy!$C$7:$J$7,0)),"") | D7: =IFERROR(INDEX(Mindspace!$C:$J,14,MATCH($B$2,Mindspace!$C$7:$J$7,0)),"") | E7: =IFERROR(INDEX(Brookfield!$C:$J,14,MATCH($B$2,Brookfield!$C$7:$J$7,0)),"") | F7: =IFERROR(INDEX(Nexus!$C:$J,14,MATCH($B$2,Nexus!$C$7:$J$7,0)),"") | G7: =IFERROR(INDEX('Knowledge (KRT)'!$C:$J,14,MATCH($B$2,'Knowledge (KRT)'!$C$7:$J$7,0)),"") | H7: =IFERROR(INDEX(Bagmane!$C:$J,14,MATCH($B$2,Bagmane!$C$7:$J$7,0)),"")
A8: EBITDA | B8: INR cr | C8: =IFERROR(INDEX(Embassy!$C:$J,15,MATCH($B$2,Embassy!$C$7:$J$7,0)),"") | D8: =IFERROR(INDEX(Mindspace!$C:$J,15,MATCH($B$2,Mindspace!$C$7:$J$7,0)),"") | E8: =IFERROR(INDEX(Brookfield!$C:$J,15,MATCH($B$2,Brookfield!$C$7:$J$7,0)),"") | F8: =IFERROR(INDEX(Nexus!$C:$J,15,MATCH($B$2,Nexus!$C$7:$J$7,0)),"") | G8: =IFERROR(INDEX('Knowledge (KRT)'!$C:$J,15,MATCH($B$2,'Knowledge (KRT)'!$C$7:$J$7,0)),"") | H8: =IFERROR(INDEX(Bagmane!$C:$J,15,MATCH($B$2,Bagmane!$C$7:$J$7,0)),"")
A9: NDCF | B9: INR cr | C9: =IFERROR(INDEX(Embassy!$C:$J,23,MATCH($B$2,Embassy!$C$7:$J$7,0)),"") | D9: =IFERROR(INDEX(Mindspace!$C:$J,23,MATCH($B$2,Mindspace!$C$7:$J$7,0)),"") | E9: =IFERROR(INDEX(Brookfield!$C:$J,23,MATCH($B$2,Brookfield!$C$7:$J$7,0)),"") | F9: =IFERROR(INDEX(Nexus!$C:$J,23,MATCH($B$2,Nexus!$C$7:$J$7,0)),"") | G9: =IFERROR(INDEX('Knowledge (KRT)'!$C:$J,23,MATCH($B$2,'Knowledge (KRT)'!$C$7:$J$7,0)),"") | H9: =IFERROR(INDEX(Bagmane!$C:$J,23,MATCH($B$2,Bagmane!$C$7:$J$7,0)),"")
A10: Total Distribution | B10: INR cr | C10: =IFERROR(INDEX(Embassy!$C:$J,24,MATCH($B$2,Embassy!$C$7:$J$7,0)),"") | D10: =IFERROR(INDEX(Mindspace!$C:$J,24,MATCH($B$2,Mindspace!$C$7:$J$7,0)),"") | E10: =IFERROR(INDEX(Brookfield!$C:$J,24,MATCH($B$2,Brookfield!$C$7:$J$7,0)),"") | F10: =IFERROR(INDEX(Nexus!$C:$J,24,MATCH($B$2,Nexus!$C$7:$J$7,0)),"") | G10: =IFERROR(INDEX('Knowledge (KRT)'!$C:$J,24,MATCH($B$2,'Knowledge (KRT)'!$C$7:$J$7,0)),"") | H10: =IFERROR(INDEX(Bagmane!$C:$J,24,MATCH($B$2,Bagmane!$C$7:$J$7,0)),"")
A11: Distribution per Unit (DPU) | B11: INR/unit | C11: =IFERROR(INDEX(Embassy!$C:$J,25,MATCH($B$2,Embassy!$C$7:$J$7,0)),"") | D11: =IFERROR(INDEX(Mindspace!$C:$J,25,MATCH($B$2,Mindspace!$C$7:$J$7,0)),"") | E11: =IFERROR(INDEX(Brookfield!$C:$J,25,MATCH($B$2,Brookfield!$C$7:$J$7,0)),"") | F11: =IFERROR(INDEX(Nexus!$C:$J,25,MATCH($B$2,Nexus!$C$7:$J$7,0)),"") | G11: =IFERROR(INDEX('Knowledge (KRT)'!$C:$J,25,MATCH($B$2,'Knowledge (KRT)'!$C$7:$J$7,0)),"") | H11: =IFERROR(INDEX(Bagmane!$C:$J,25,MATCH($B$2,Bagmane!$C$7:$J$7,0)),"")
A12: Annual Distribution Yield | B12: % | C12: =IFERROR(INDEX(Embassy!$C:$J,39,MATCH($B$2,Embassy!$C$7:$J$7,0)),"") | D12: =IFERROR(INDEX(Mindspace!$C:$J,39,MATCH($B$2,Mindspace!$C$7:$J$7,0)),"") | E12: =IFERROR(INDEX(Brookfield!$C:$J,39,MATCH($B$2,Brookfield!$C$7:$J$7,0)),"") | F12: =IFERROR(INDEX(Nexus!$C:$J,39,MATCH($B$2,Nexus!$C$7:$J$7,0)),"") | G12: =IFERROR(INDEX('Knowledge (KRT)'!$C:$J,39,MATCH($B$2,'Knowledge (KRT)'!$C$7:$J$7,0)),"") | H12: =IFERROR(INDEX(Bagmane!$C:$J,39,MATCH($B$2,Bagmane!$C$7:$J$7,0)),"")
A13: Market Capitalisation | B13: INR cr | C13: =IFERROR(INDEX(Embassy!$C:$J,38,MATCH($B$2,Embassy!$C$7:$J$7,0)),"") | D13: =IFERROR(INDEX(Mindspace!$C:$J,38,MATCH($B$2,Mindspace!$C$7:$J$7,0)),"") | E13: =IFERROR(INDEX(Brookfield!$C:$J,38,MATCH($B$2,Brookfield!$C$7:$J$7,0)),"") | F13: =IFERROR(INDEX(Nexus!$C:$J,38,MATCH($B$2,Nexus!$C$7:$J$7,0)),"") | G13: =IFERROR(INDEX('Knowledge (KRT)'!$C:$J,38,MATCH($B$2,'Knowledge (KRT)'!$C$7:$J$7,0)),"") | H13: =IFERROR(INDEX(Bagmane!$C:$J,38,MATCH($B$2,Bagmane!$C$7:$J$7,0)),"")
A14: GAV / AUM | B14: INR cr | C14: =IFERROR(INDEX(Embassy!$C:$J,28,MATCH($B$2,Embassy!$C$7:$J$7,0)),"") | D14: =IFERROR(INDEX(Mindspace!$C:$J,28,MATCH($B$2,Mindspace!$C$7:$J$7,0)),"") | E14: =IFERROR(INDEX(Brookfield!$C:$J,28,MATCH($B$2,Brookfield!$C$7:$J$7,0)),"") | F14: =IFERROR(INDEX(Nexus!$C:$J,28,MATCH($B$2,Nexus!$C$7:$J$7,0)),"") | G14: =IFERROR(INDEX('Knowledge (KRT)'!$C:$J,28,MATCH($B$2,'Knowledge (KRT)'!$C$7:$J$7,0)),"") | H14: =IFERROR(INDEX(Bagmane!$C:$J,28,MATCH($B$2,Bagmane!$C$7:$J$7,0)),"")
A15: Net Debt | B15: INR cr | C15: =IFERROR(INDEX(Embassy!$C:$J,31,MATCH($B$2,Embassy!$C$7:$J$7,0)),"") | D15: =IFERROR(INDEX(Mindspace!$C:$J,31,MATCH($B$2,Mindspace!$C$7:$J$7,0)),"") | E15: =IFERROR(INDEX(Brookfield!$C:$J,31,MATCH($B$2,Brookfield!$C$7:$J$7,0)),"") | F15: =IFERROR(INDEX(Nexus!$C:$J,31,MATCH($B$2,Nexus!$C$7:$J$7,0)),"") | G15: =IFERROR(INDEX('Knowledge (KRT)'!$C:$J,31,MATCH($B$2,'Knowledge (KRT)'!$C$7:$J$7,0)),"") | H15: =IFERROR(INDEX(Bagmane!$C:$J,31,MATCH($B$2,Bagmane!$C$7:$J$7,0)),"")
A16: Loan-to-Value (LTV) | B16: % | C16: =IFERROR(INDEX(Embassy!$C:$J,33,MATCH($B$2,Embassy!$C$7:$J$7,0)),"") | D16: =IFERROR(INDEX(Mindspace!$C:$J,33,MATCH($B$2,Mindspace!$C$7:$J$7,0)),"") | E16: =IFERROR(INDEX(Brookfield!$C:$J,33,MATCH($B$2,Brookfield!$C$7:$J$7,0)),"") | F16: =IFERROR(INDEX(Nexus!$C:$J,33,MATCH($B$2,Nexus!$C$7:$J$7,0)),"") | G16: =IFERROR(INDEX('Knowledge (KRT)'!$C:$J,33,MATCH($B$2,'Knowledge (KRT)'!$C$7:$J$7,0)),"") | H16: =IFERROR(INDEX(Bagmane!$C:$J,33,MATCH($B$2,Bagmane!$C$7:$J$7,0)),"")
A17: GLA | B17: Msf | C17: =IFERROR(INDEX(Embassy!$C:$J,42,MATCH($B$2,Embassy!$C$7:$J$7,0)),"") | D17: =IFERROR(INDEX(Mindspace!$C:$J,42,MATCH($B$2,Mindspace!$C$7:$J$7,0)),"") | E17: =IFERROR(INDEX(Brookfield!$C:$J,42,MATCH($B$2,Brookfield!$C$7:$J$7,0)),"") | F17: =IFERROR(INDEX(Nexus!$C:$J,42,MATCH($B$2,Nexus!$C$7:$J$7,0)),"") | G17: =IFERROR(INDEX('Knowledge (KRT)'!$C:$J,42,MATCH($B$2,'Knowledge (KRT)'!$C$7:$J$7,0)),"") | H17: =IFERROR(INDEX(Bagmane!$C:$J,42,MATCH($B$2,Bagmane!$C$7:$J$7,0)),"")
A18: Committed Occupancy | B18: % | C18: =IFERROR(INDEX(Embassy!$C:$J,45,MATCH($B$2,Embassy!$C$7:$J$7,0)),"") | D18: =IFERROR(INDEX(Mindspace!$C:$J,45,MATCH($B$2,Mindspace!$C$7:$J$7,0)),"") | E18: =IFERROR(INDEX(Brookfield!$C:$J,45,MATCH($B$2,Brookfield!$C$7:$J$7,0)),"") | F18: =IFERROR(INDEX(Nexus!$C:$J,45,MATCH($B$2,Nexus!$C$7:$J$7,0)),"") | G18: =IFERROR(INDEX('Knowledge (KRT)'!$C:$J,45,MATCH($B$2,'Knowledge (KRT)'!$C$7:$J$7,0)),"") | H18: =IFERROR(INDEX(Bagmane!$C:$J,45,MATCH($B$2,Bagmane!$C$7:$J$7,0)),"")
A19: WALE | B19: years | C19: =IFERROR(INDEX(Embassy!$C:$J,47,MATCH($B$2,Embassy!$C$7:$J$7,0)),"") | D19: =IFERROR(INDEX(Mindspace!$C:$J,47,MATCH($B$2,Mindspace!$C$7:$J$7,0)),"") | E19: =IFERROR(INDEX(Brookfield!$C:$J,47,MATCH($B$2,Brookfield!$C$7:$J$7,0)),"") | F19: =IFERROR(INDEX(Nexus!$C:$J,47,MATCH($B$2,Nexus!$C$7:$J$7,0)),"") | G19: =IFERROR(INDEX('Knowledge (KRT)'!$C:$J,47,MATCH($B$2,'Knowledge (KRT)'!$C$7:$J$7,0)),"") | H19: =IFERROR(INDEX(Bagmane!$C:$J,47,MATCH($B$2,Bagmane!$C$7:$J$7,0)),"")
A21: * Bagmane figures are proforma/combined from its RHP (Trust listed May 2026; pre-operational at FY2026 year-end).
A22: Green/grey figures pull live from the individual REIT sheets - edit data there, not here.

Sheet Embassy
A1: Embassy REIT - Key Financials & Operating Metrics
A2: Sponsor: Embassy Group / Blackstone. All INR figures in INR crore (cr) unless stated. 1 crore = 10 million. FY ends 31 March.
A3: Hover a cell for its Source (report + page + original figure). Grey italic = auto-calculated. YoY% = FY2026 vs FY2025.
C6: CONSOLIDATED | L6: STANDALONE
A7: Metric | B7: Unit | C7: FY2019 | D7: FY2020 | E7: FY2021 | F7: FY2022 | G7: FY2023 | H7: FY2024 | I7: FY2025 | J7: FY2026 | K7: YoY% | L7: FY2019 | M7: FY2020 | N7: FY2021 | O7: FY2022 | P7: FY2023 | Q7: FY2024 | R7: FY2025 | S7: FY2026 | T7: YoY%
A8: INCOME STATEMENT
A9: Revenue from Operations | B9: INR cr | C9: 1877.081 | D9: 2144.922 | E9: 2360.32 | F9: 2962.605 | G9: 3419.543 | H9: 3685.182 | I9: 4038.932 | J9: 4582.356 | K9: =IFERROR((J9-I9)/I9,"") | T9: =IFERROR((S9-R9)/R9,"")
A10: Other Income | B10: INR cr | C10: 153.927 | D10: 99.035 | E10: 118.526 | F10: 126.927 | G10: 144.124 | H10: 203.084 | I10: 142.367 | J10: 93.488 | K10: =IFERROR((J10-I10)/I10,"") | N10: 947.475 | O10: 2113.605 | P10: 2061.986 | Q10: 1905.453 | R10: 1633.517 | S10: 2173.532 | T10: =IFERROR((S10-R10)/R10,"")
A11: Total Income | B11: INR cr | C11: =IF(AND(C9="",C10=""),"",N(C9)+N(C10)) | D11: =IF(AND(D9="",D10=""),"",N(D9)+N(D10)) | E11: =IF(AND(E9="",E10=""),"",N(E9)+N(E10)) | F11: =IF(AND(F9="",F10=""),"",N(F9)+N(F10)) | G11: =IF(AND(G9="",G10=""),"",N(G9)+N(G10)) | H11: =IF(AND(H9="",H10=""),"",N(H9)+N(H10)) | I11: =IF(AND(I9="",I10=""),"",N(I9)+N(I10)) | J11: =IF(AND(J9="",J10=""),"",N(J9)+N(J10)) | K11: =IFERROR((J11-I11)/I11,"") | L11: =IF(AND(L9="",L10=""),"",N(L9)+N(L10)) | M11: =IF(AND(M9="",M10=""),"",N(M9)+N(M10)) | N11: =IF(AND(N9="",N10=""),"",N(N9)+N(N10)) | O11: =IF(AND(O9="",O10=""),"",N(O9)+N(O10)) | P11: =IF(AND(P9="",P10=""),"",N(P9)+N(P10)) | Q11: =IF(AND(Q9="",Q10=""),"",N(Q9)+N(Q10)) | R11: =IF(AND(R9="",R10=""),"",N(R9)+N(R10)) | S11: =IF(AND(S9="",S10=""),"",N(S9)+N(S10)) | T11: =IFERROR((S11-R11)/R11,"")
A12: Property / Operating Expenses | B12: INR cr | C12: 237.656 | D12: 184.284 | E12: 220.801 | F12: 324.331 | G12: 399.633 | H12: 524.895 | I12: 561.366 | J12: 585.526 | K12: =IFERROR((J12-I12)/I12,"") | T12: =IFERROR((S12-R12)/R12,"")
A13: Net Operating Income (NOI) | B13: INR cr | C13: 1574.1 | D13: 1817 | F13: 2491.1 | G13: 2766.28 | H13: 2981.9 | I13: 3283.5 | J13: 3760 | K13: =IFERROR((J13-I13)/I13,"") | T13: =IFERROR((S13-R13)/R13,"")
A14: NOI Margin | B14: % | C14: =IF(OR(C13="",C9="",N(C9)=0),"",C13/C9) | D14: =IF(OR(D13="",D9="",N(D9)=0),"",D13/D9) | E14: =IF(OR(E13="",E9="",N(E9)=0),"",E13/E9) | F14: =IF(OR(F13="",F9="",N(F9)=0),"",F13/F9) | G14: =IF(OR(G13="",G9="",N(G9)=0),"",G13/G9) | H14: =IF(OR(H13="",H9="",N(H9)=0),"",H13/H9) | I14: =IF(OR(I13="",I9="",N(I9)=0),"",I13/I9) | J14: =IF(OR(J13="",J9="",N(J9)=0),"",J13/J9) | L14: =IF(OR(L13="",L9="",N(L9)=0),"",L13/L9) | M14: =IF(OR(M13="",M9="",N(M9)=0),"",M13/M9) | N14: =IF(OR(N13="",N9="",N(N9)=0),"",N13/N9) | O14: =IF(OR(O13="",O9="",N(O9)=0),"",O13/O9) | P14: =IF(OR(P13="",P9="",N(P9)=0),"",P13/P9) | Q14: =IF(OR(Q13="",Q9="",N(Q9)=0),"",Q13/Q9) | R14: =IF(OR(R13="",R9="",N(R9)=0),"",R13/R9) | S14: =IF(OR(S13="",S9="",N(S9)=0),"",S13/S9)
A15: EBITDA | B15: INR cr | C15: 1513.656 | D15: 1764.677 | E15: 1969.321 | F15: 2425.017 | G15: 2688.499 | H15: 2972.411 | I15: 3188.75 | J15: 3602.234 | K15: =IFERROR((J15-I15)/I15,"") | L15: -9.447 | N15: 1189.896 | O15: 2076.255 | P15: 2013.282 | T15: =IFERROR((S15-R15)/R15,"")
A16: EBITDA Margin | B16: % | C16: =IF(OR(C15="",C9="",N(C9)=0),"",C15/C9) | D16: =IF(OR(D15="",D9="",N(D9)=0),"",D15/D9) | E16: =IF(OR(E15="",E9="",N(E9)=0),"",E15/E9) | F16: =IF(OR(F15="",F9="",N(F9)=0),"",F15/F9) | G16: =IF(OR(G15="",G9="",N(G9)=0),"",G15/G9) | H16: =IF(OR(H15="",H9="",N(H9)=0),"",H15/H9) | I16: =IF(OR(I15="",I9="",N(I9)=0),"",I15/I9) | J16: =IF(OR(J15="",J9="",N(J9)=0),"",J15/J9) | L16: =IF(OR(L15="",L9="",N(L9)=0),"",L15/L9) | M16: =IF(OR(M15="",M9="",N(M9)=0),"",M15/M9) | N16: =IF(OR(N15="",N9="",N(N9)=0),"",N15/N9) | O16: =IF(OR(O15="",O9="",N(O9)=0),"",O15/O9) | P16: =IF(OR(P15="",P9="",N(P9)=0),"",P15/P9) | Q16: =IF(OR(Q15="",Q9="",N(Q9)=0),"",Q15/Q9) | R16: =IF(OR(R15="",R9="",N(R9)=0),"",R15/R9) | S16: =IF(OR(S15="",S9="",N(S9)=0),"",S15/S9)
A17: Finance Costs | B17: INR cr | C17: 705.981 | D17: 380.354 | E17: 645.289 | F17: 828.528 | G17: 976.063 | H17: 1087.235 | I17: 1328.625 | J17: 1495.042 | K17: =IFERROR((J17-I17)/I17,"") | L17: 0 | N17: 469.865 | O17: 646.23 | P17: 601.763 | Q17: 720.717 | R17: 652.053 | S17: 810.413 | T17: =IFERROR((S17-R17)/R17,"")
A18: Depreciation & Amortisation | B18: INR cr | C18: 356.319 | D18: 528.124 | E18: 570.697 | F18: 796.463 | G18: 1128.416 | H18: 968.989 | I18: 1141.515 | J18: 1265.785 | K18: =IFERROR((J18-I18)/I18,"") | T18: =IFERROR((S18-R18)/R18,"")
A19: Profit Before Tax (PBT) | B19: INR cr | C19: 566.509 | D19: 795.534 | E19: 753.887 | F19: 896.24 | G19: 661.77 | H19: 1089.073 | I19: 193.042 | J19: 1133.571 | K19: =IFERROR((J19-I19)/I19,"") | L19: -9.447 | N19: 451.22 | O19: 1344.277 | P19: 1282.007 | Q19: 1208.576 | R19: 631.4 | S19: 1314.927 | T19: =IFERROR((S19-R19)/R19,"")
A20: Profit After Tax (PAT) | B20: INR cr | C20: 365.329 | D20: 765.534 | E20: 698.353 | F20: 888.385 | G20: 505.958 | H20: 964.028 | I20: 1624.436 | J20: 338.545 | K20: =IFERROR((J20-I20)/I20,"") | L20: -9.447 | N20: 447.442 | O20: 1339.742 | P20: 1279.148 | Q20: 1206.824 | R20: 631.152 | S20: 1313.495 | T20: =IFERROR((S20-R20)/R20,"")
A21: PAT Margin | B21: % | C21: =IF(OR(C20="",C9="",N(C9)=0),"",C20/C9) | D21: =IF(OR(D20="",D9="",N(D9)=0),"",D20/D9) | E21: =IF(OR(E20="",E9="",N(E9)=0),"",E20/E9) | F21: =IF(OR(F20="",F9="",N(F9)=0),"",F20/F9) | G21: =IF(OR(G20="",G9="",N(G9)=0),"",G20/G9) | H21: =IF(OR(H20="",H9="",N(H9)=0),"",H20/H9) | I21: =IF(OR(I20="",I9="",N(I9)=0),"",I20/I9) | J21: =IF(OR(J20="",J9="",N(J9)=0),"",J20/J9) | L21: =IF(OR(L20="",L9="",N(L9)=0),"",L20/L9) | M21: =IF(OR(M20="",M9="",N(M9)=0),"",M20/M9) | N21: =IF(OR(N20="",N9="",N(N9)=0),"",N20/N9) | O21: =IF(OR(O20="",O9="",N(O9)=0),"",O20/O9) | P21: =IF(OR(P20="",P9="",N(P9)=0),"",P20/P9) | Q21: =IF(OR(Q20="",Q9="",N(Q9)=0),"",Q20/Q9) | R21: =IF(OR(R20="",R9="",N(R9)=0),"",R20/R9) | S21: =IF(OR(S20="",S9="",N(S9)=0),"",S20/S9)
A22: DISTRIBUTIONS & CASH FLOW
A23: Net Distributable Cash Flow (NDCF) | B23: INR cr | D23: 1886.592 | E23: 1835.62 | F23: 2063.819 | G23: 2060.819 | H23: 2024.665 | I23: 2184.553 | J23: 2400.831 | K23: =IFERROR((J23-I23)/I23,"") | L23: n/a | M23: n/a | N23: n/a | O23: n/a | P23: n/a | Q23: n/a | R23: n/a | S23: n/a | T23: n/a
A24: Total Distribution | B24: INR cr | D24: 1882.092 | E24: 1836.409 | F24: 2062.617 | G24: 2057.877 | H24: 2021.858 | I24: 2181.103 | J24: 2396.275 | K24: =IFERROR((J24-I24)/I24,"") | L24: n/a | M24: n/a | N24: n/a | O24: n/a | P24: n/a | Q24: n/a | R24: n/a | S24: n/a | T24: n/a
A25: Distribution per Unit (DPU) | B25: INR/unit | D25: 24.39 | E25: 21.48 | F25: 21.76 | G25: 21.71 | H25: 21.33 | I25: 23.01 | J25: 25.28 | K25: =IFERROR((J25-I25)/I25,"") | L25: n/a | M25: n/a | N25: n/a | O25: n/a | P25: n/a | Q25: n/a | R25: n/a | S25: n/a | T25: n/a
A26: NDCF Payout Ratio | B26: % | C26: =IF(OR(C24="",C23="",N(C23)=0),"",C24/C23) | D26: =IF(OR(D24="",D23="",N(D23)=0),"",D24/D23) | E26: =IF(OR(E24="",E23="",N(E23)=0),"",E24/E23) | F26: =IF(OR(F24="",F23="",N(F23)=0),"",F24/F23) | G26: =IF(OR(G24="",G23="",N(G23)=0),"",G24/G23) | H26: =IF(OR(H24="",H23="",N(H23)=0),"",H24/H23) | I26: =IF(OR(I24="",I23="",N(I23)=0),"",I24/I23) | J26: =IF(OR(J24="",J23="",N(J23)=0),"",J24/J23) | L26: n/a | M26: n/a | N26: n/a | O26: n/a | P26: n/a | Q26: n/a | R26: n/a | S26: n/a | T26: n/a
A27: BALANCE SHEET & LEVERAGE
A28: Gross Asset Value (GAV) / AUM | B28: INR cr | C28: 31612.4 | D28: 32974.625 | E28: 46605.125 | F28: 49007.8 | G28: 51414.114 | H28: 54911.478 | I28: 60567.286 | J28: 69943.737 | K28: =IFERROR((J28-I28)/I28,"") | L28: n/a | M28: n/a | N28: n/a | O28: n/a | P28: n/a | Q28: n/a | R28: n/a | S28: n/a | T28: n/a
A29: Gross Debt | B29: INR cr | C29: 7124.565 | D29: 5617.051 | E29: 10622.3 | F29: 12101.352 | G29: 14805.496 | H29: 16807.953 | I29: 19807.304 | J29: 22384.789 | K29: =IFERROR((J29-I29)/I29,"") | L29: 0 | N29: 8331.91 | O29: 7449.133 | P29: 9465.781 | Q29: 9144.66 | R29: 8064.714 | S29: 12114.256 | T29: =IFERROR((S29-R29)/R29,"")
A30: Cash & Cash Equivalents | B30: INR cr | C30: 4961.271 | D30: 324.916 | E30: 917.478 | F30: 588.449 | G30: 817.348 | H30: 1026.847 | I30: 676.586 | J30: 980.376 | K30: =IFERROR((J30-I30)/I30,"") | L30: 4281.853 | N30: 717.126 | O30: 520.047 | P30: 528.015 | Q30: 518.712 | R30: 0.966 | S30: 153.643 | T30: =IFERROR((S30-R30)/R30,"")
A31: Net Debt | B31: INR cr | C31: =IF(C29="","",C29-N(C30)) | D31: =IF(D29="","",D29-N(D30)) | E31: =IF(E29="","",E29-N(E30)) | F31: =IF(F29="","",F29-N(F30)) | G31: =IF(G29="","",G29-N(G30)) | H31: =IF(H29="","",H29-N(H30)) | I31: =IF(I29="","",I29-N(I30)) | J31: =IF(J29="","",J29-N(J30)) | K31: =IFERROR((J31-I31)/I31,"") | L31: =IF(L29="","",L29-N(L30)) | M31: =IF(M29="","",M29-N(M30)) | N31: =IF(N29="","",N29-N(N30)) | O31: =IF(O29="","",O29-N(O30)) | P31: =IF(P29="","",P29-N(P30)) | Q31: =IF(Q29="","",Q29-N(Q30)) | R31: =IF(R29="","",R29-N(R30)) | S31: =IF(S29="","",S29-N(S30)) | T31: =IFERROR((S31-R31)/R31,"")
A32: Net Worth / Unitholders Equity | B32: INR cr | C32: 22894.479 | D32: 22317.784 | E32: 27093.067 | F32: 25886.69 | G32: 24368.298 | H32: 23274.175 | I32: 22761.16 | J32: 20780.179 | K32: =IFERROR((J32-I32)/I32,"") | L32: 22894.479 | N32: 26557.922 | O32: 25802.819 | P32: 25057.266 | Q32: 24205.265 | R32: 22698.917 | S32: 21693.862 | T32: =IFERROR((S32-R32)/R32,"")
A33: Loan-to-Value (LTV) | B33: % | C33: =IF(OR(C31="",C28="",N(C28)=0),"",C31/C28) | D33: =IF(OR(D31="",D28="",N(D28)=0),"",D31/D28) | E33: =IF(OR(E31="",E28="",N(E28)=0),"",E31/E28) | F33: =IF(OR(F31="",F28="",N(F28)=0),"",F31/F28) | G33: =IF(OR(G31="",G28="",N(G28)=0),"",G31/G28) | H33: =IF(OR(H31="",H28="",N(H28)=0),"",H31/H28) | I33: =IF(OR(I31="",I28="",N(I28)=0),"",I31/I28) | J33: =IF(OR(J31="",J28="",N(J28)=0),"",J31/J28) | L33: =IF(OR(L31="",L28="",N(L28)=0),"",L31/L28) | M33: =IF(OR(M31="",M28="",N(M28)=0),"",M31/M28) | N33: =IF(OR(N31="",N28="",N(N28)=0),"",N31/N28) | O33: =IF(OR(O31="",O28="",N(O28)=0),"",O31/O28) | P33: =IF(OR(P31="",P28="",N(P28)=0),"",P31/P28) | Q33: =IF(OR(Q31="",Q28="",N(Q28)=0),"",Q31/Q28) | R33: =IF(OR(R31="",R28="",N(R28)=0),"",R31/R28) | S33: =IF(OR(S31="",S28="",N(S28)=0),"",S31/S28)
A34: NAV per Unit | B34: INR/unit | C34: 362 | D34: 374.64 | E34: 387.54 | F34: 393.9 | G34: 394.88 | H34: 401.59 | I34: 423.22 | J34: 491.62 | K34: =IFERROR((J34-I34)/I34,"") | L34: n/a | M34: n/a | N34: n/a | O34: n/a | P34: n/a | Q34: n/a | R34: n/a | S34: n/a | T34: n/a
A35: MARKET DATA
A36: Units Outstanding | B36: mn units | C36: 771.67 | D36: 771.67 | E36: 947.89 | F36: 947.89 | G36: 947.89 | H36: 947.89 | I36: 947.89 | J36: 947.89 | K36: =IFERROR((J36-I36)/I36,"") | L36: n/a | M36: n/a | N36: n/a | O36: n/a | P36: n/a | Q36: n/a | R36: n/a | S36: n/a | T36: n/a
A37: Unit Price (period-end) | B37: INR/unit | E37: 325.45 | F37: 370.11 | G37: 312.6 | H37: 369.61 | I37: 365.49 | J37: 420.3 | K37: =IFERROR((J37-I37)/I37,"") | L37: n/a | M37: n/a | N37: n/a | O37: n/a | P37: n/a | Q37: n/a | R37: n/a | S37: n/a | T37: n/a
A38: Market Capitalisation | B38: INR cr | C38: =IF(OR(C36="",C37=""),"",C36*C37/10) | D38: =IF(OR(D36="",D37=""),"",D36*D37/10) | E38: =IF(OR(E36="",E37=""),"",E36*E37/10) | F38: =IF(OR(F36="",F37=""),"",F36*F37/10) | G38: =IF(OR(G36="",G37=""),"",G36*G37/10) | H38: =IF(OR(H36="",H37=""),"",H36*H37/10) | I38: =IF(OR(I36="",I37=""),"",I36*I37/10) | J38: =IF(OR(J36="",J37=""),"",J36*J37/10) | K38: =IFERROR((J38-I38)/I38,"") | L38: n/a | M38: n/a | N38: n/a | O38: n/a | P38: n/a | Q38: n/a | R38: n/a | S38: n/a | T38: n/a
A39: Annual Distribution Yield | B39: % | C39: =IF(OR(C25="",C37="",N(C37)=0),"",C25/C37) | D39: =IF(OR(D25="",D37="",N(D37)=0),"",D25/D37) | E39: =IF(OR(E25="",E37="",N(E37)=0),"",E25/E37) | F39: =IF(OR(F25="",F37="",N(F37)=0),"",F25/F37) | G39: =IF(OR(G25="",G37="",N(G37)=0),"",G25/G37) | H39: =IF(OR(H25="",H37="",N(H37)=0),"",H25/H37) | I39: =IF(OR(I25="",I37="",N(I37)=0),"",I25/I37) | J39: =IF(OR(J25="",J37="",N(J37)=0),"",J25/J37) | L39: n/a | M39: n/a | N39: n/a | O39: n/a | P39: n/a | Q39: n/a | R39: n/a | S39: n/a | T39: n/a
A40: Cost of Debt | B40: % | D40: 0.095 | E40: 0.0781 | F40: 0.067 | G40: 0.072 | H40: 0.078 | I40: 0.079 | J40: 0.0725 | L40: n/a | M40: n/a | N40: n/a | O40: n/a | P40: n/a | Q40: n/a | R40: n/a | S40: n/a | T40: n/a
A41: PORTFOLIO & OPERATING METRICS (consolidated)
A42: Total Leasable Area (GLA) | B42: Msf | C42: 32.7 | D42: 33.3 | E42: 42.4 | F42: 42.8 | G42: 45 | H42: 45.4 | I42: 51.1 | J42: 52.5 | K42: =IFERROR((J42-I42)/I42,"") | L42: n/a | M42: n/a | N42: n/a | O42: n/a | P42: n/a | Q42: n/a | R42: n/a | S42: n/a | T42: n/a
...

Sheet Mindspace
A1: Mindspace REIT - Key Financials & Operating Metrics
A2: Sponsor: K Raheja Corp. All INR figures in INR crore (cr) unless stated. 1 crore = 10 million. FY ends 31 March.
A3: Hover a cell for its Source (report + page + original figure). Grey italic = auto-calculated. YoY% = FY2026 vs FY2025.
C6: CONSOLIDATED | L6: STANDALONE
A7: Metric | B7: Unit | C7: FY2019 | D7: FY2020 | E7: FY2021 | F7: FY2022 | G7: FY2023 | H7: FY2024 | I7: FY2025 | J7: FY2026 | K7: YoY% | L7: FY2019 | M7: FY2020 | N7: FY2021 | O7: FY2022 | P7: FY2023 | Q7: FY2024 | R7: FY2025 | S7: FY2026 | T7: YoY%
A8: INCOME STATEMENT
A9: Revenue from Operations | B9: INR cr | E9: 1138.1 | F9: 1750.1 | H9: 2429.2 | I9: 2596.109 | J9: 3216.346 | K9: =IFERROR((J9-I9)/I9,"") | T9: =IFERROR((S9-R9)/R9,"")
A10: Other Income | B10: INR cr | E10: 5.1 | F10: 8.8 | H10: 14.501 | I10: 15.158 | J10: 76.741 | K10: =IFERROR((J10-I10)/I10,"") | N10: 1.2 | O10: 1.1 | Q10: 0.69 | R10: 0.464 | S10: 5.335 | T10: =IFERROR((S10-R10)/R10,"")
A11: Total Income | B11: INR cr | C11: =IF(AND(C9="",C10=""),"",N(C9)+N(C10)) | D11: =IF(AND(D9="",D10=""),"",N(D9)+N(D10)) | E11: =IF(AND(E9="",E10=""),"",N(E9)+N(E10)) | F11: =IF(AND(F9="",F10=""),"",N(F9)+N(F10)) | G11: =IF(AND(G9="",G10=""),"",N(G9)+N(G10)) | H11: =IF(AND(H9="",H10=""),"",N(H9)+N(H10)) | I11: =IF(AND(I9="",I10=""),"",N(I9)+N(I10)) | J11: =IF(AND(J9="",J10=""),"",N(J9)+N(J10)) | K11: =IFERROR((J11-I11)/I11,"") | L11: =IF(AND(L9="",L10=""),"",N(L9)+N(L10)) | M11: =IF(AND(M9="",M10=""),"",N(M9)+N(M10)) | N11: =IF(AND(N9="",N10=""),"",N(N9)+N(N10)) | O11: =IF(AND(O9="",O10=""),"",N(O9)+N(O10)) | P11: =IF(AND(P9="",P10=""),"",N(P9)+N(P10)) | Q11: =IF(AND(Q9="",Q10=""),"",N(Q9)+N(Q10)) | R11: =IF(AND(R9="",R10=""),"",N(R9)+N(R10)) | S11: =IF(AND(S9="",S10=""),"",N(S9)+N(S10)) | T11: =IFERROR((S11-R11)/R11,"")
A12: Property / Operating Expenses | B12: INR cr | K12: =IFERROR((J12-I12)/I12,"") | T12: =IFERROR((S12-R12)/R12,"")
A13: Net Operating Income (NOI) | B13: INR cr | E13: 1374.1 | F13: 1486.4 | H13: 1895.9 | I13: 2061.6 | J13: 2663.6 | K13: =IFERROR((J13-I13)/I13,"") | T13: =IFERROR((S13-R13)/R13,"")
A14: NOI Margin | B14: % | C14: =IF(OR(C13="",C9="",N(C9)=0),"",C13/C9) | D14: =IF(OR(D13="",D9="",N(D9)=0),"",D13/D9) | E14: =IF(OR(E13="",E9="",N(E9)=0),"",E13/E9) | F14: =IF(OR(F13="",F9="",N(F9)=0),"",F13/F9) | G14: =IF(OR(G13="",G9="",N(G9)=0),"",G13/G9) | H14: =IF(OR(H13="",H9="",N(H9)=0),"",H13/H9) | I14: =IF(OR(I13="",I9="",N(I9)=0),"",I13/I9) | J14: =IF(OR(J13="",J9="",N(J9)=0),"",J13/J9) | L14: =IF(OR(L13="",L9="",N(L9)=0),"",L13/L9) | M14: =IF(OR(M13="",M9="",N(M9)=0),"",M13/M9) | N14: =IF(OR(N13="",N9="",N(N9)=0),"",N13/N9) | O14: =IF(OR(O13="",O9="",N(O9)=0),"",O13/O9) | P14: =IF(OR(P13="",P9="",N(P9)=0),"",P13/P9) | Q14: =IF(OR(Q13="",Q9="",N(Q9)=0),"",Q13/Q9) | R14: =IF(OR(R13="",R9="",N(R9)=0),"",R13/R9) | S14: =IF(OR(S13="",S9="",N(S9)=0),"",S13/S9)
A15: EBITDA | B15: INR cr | E15: 846.6 | F15: 1384.3 | H15: 1798.821 | I15: 1968.161 | J15: 2514.56 | K15: =IFERROR((J15-I15)/I15,"") | N15: 606.9 | O15: 1190.3 | T15: =IFERROR((S15-R15)/R15,"")
A16: EBITDA Margin | B16: % | C16: =IF(OR(C15="",C9="",N(C9)=0),"",C15/C9) | D16: =IF(OR(D15="",D9="",N(D9)=0),"",D15/D9) | E16: =IF(OR(E15="",E9="",N(E9)=0),"",E15/E9) | F16: =IF(OR(F15="",F9="",N(F9)=0),"",F15/F9) | G16: =IF(OR(G15="",G9="",N(G9)=0),"",G15/G9) | H16: =IF(OR(H15="",H9="",N(H9)=0),"",H15/H9) | I16: =IF(OR(I15="",I9="",N(I9)=0),"",I15/I9) | J16: =IF(OR(J15="",J9="",N(J9)=0),"",J15/J9) | L16: =IF(OR(L15="",L9="",N(L9)=0),"",L15/L9) | M16: =IF(OR(M15="",M9="",N(M9)=0),"",M15/M9) | N16: =IF(OR(N15="",N9="",N(N9)=0),"",N15/N9) | O16: =IF(OR(O15="",O9="",N(O9)=0),"",O15/O9) | P16: =IF(OR(P15="",P9="",N(P9)=0),"",P15/P9) | Q16: =IF(OR(Q15="",Q9="",N(Q9)=0),"",Q15/Q9) | R16: =IF(OR(R15="",R9="",N(R9)=0),"",R15/R9) | S16: =IF(OR(S15="",S9="",N(S9)=0),"",S15/S9)
A17: Finance Costs | B17: INR cr | E17: 170.7 | F17: 264.4 | H17: 456.632 | I17: 557.273 | J17: 836.401 | K17: =IFERROR((J17-I17)/I17,"") | N17: 23 | O17: 86.7 | Q17: 222.151 | R17: 348.033 | S17: 529.302 | T17: =IFERROR((S17-R17)/R17,"")
A18: Depreciation & Amortisation | B18: INR cr | E18: 196.4 | F18: 328.9 | H18: 382.654 | I18: 405.984 | J18: 478.98 | K18: =IFERROR((J18-I18)/I18,"") | N18: 0 | O18: 0 | T18: =IFERROR((S18-R18)/R18,"")
A19: Profit Before Tax (PBT) | B19: INR cr | E19: 479.4 | F19: 714.3 | H19: 910.611 | I19: 968.153 | J19: 1172.334 | K19: =IFERROR((J19-I19)/I19,"") | N19: 583.9 | O19: 1103.6 | Q19: 1162.037 | R19: 596.847 | S19: 729.319 | T19: =IFERROR((S19-R19)/R19,"")
A20: Profit After Tax (PAT) | B20: INR cr | E20: 334.9 | F20: 447.3 | H20: 561.238 | I20: 513.746 | J20: 694.258 | K20: =IFERROR((J20-I20)/I20,"") | N20: 583.4 | O20: 1103 | Q20: 1161.198 | R20: 591.586 | S20: 724.6 | T20: =IFERROR((S20-R20)/R20,"")
A21: PAT Margin | B21: % | C21: =IF(OR(C20="",C9="",N(C9)=0),"",C20/C9) | D21: =IF(OR(D20="",D9="",N(D9)=0),"",D20/D9) | E21: =IF(OR(E20="",E9="",N(E9)=0),"",E20/E9) | F21: =IF(OR(F20="",F9="",N(F9)=0),"",F20/F9) | G21: =IF(OR(G20="",G9="",N(G9)=0),"",G20/G9) | H21: =IF(OR(H20="",H9="",N(H9)=0),"",H20/H9) | I21: =IF(OR(I20="",I9="",N(I9)=0),"",I20/I9) | J21: =IF(OR(J20="",J9="",N(J9)=0),"",J20/J9) | L21: =IF(OR(L20="",L9="",N(L9)=0),"",L20/L9) | M21: =IF(OR(M20="",M9="",N(M9)=0),"",M20/M9) | N21: =IF(OR(N20="",N9="",N(N9)=0),"",N20/N9) | O21: =IF(OR(O20="",O9="",N(O9)=0),"",O20/O9) | P21: =IF(OR(P20="",P9="",N(P9)=0),"",P20/P9) | Q21: =IF(OR(Q20="",Q9="",N(Q9)=0),"",Q20/Q9) | R21: =IF(OR(R20="",R9="",N(R9)=0),"",R20/R9) | S21: =IF(OR(S20="",S9="",N(S9)=0),"",S20/S9)
A22: DISTRIBUTIONS & CASH FLOW
A23: Net Distributable Cash Flow (NDCF) | B23: INR cr | E23: 570.6 | F23: 1098.4 | H23: 1143 | I23: 1321.435 | J23: 1528.778 | K23: =IFERROR((J23-I23)/I23,"") | L23: n/a | M23: n/a | N23: n/a | O23: n/a | P23: n/a | Q23: n/a | R23: n/a | S23: n/a | T23: n/a
A24: Total Distribution | B24: INR cr | E24: 568.7 | F24: 1094.1 | H24: 1136.2 | I24: 1312.1 | J24: 1516.356 | K24: =IFERROR((J24-I24)/I24,"") | L24: n/a | M24: n/a | N24: n/a | O24: n/a | P24: n/a | Q24: n/a | R24: n/a | S24: n/a | T24: n/a
A25: Distribution per Unit (DPU) | B25: INR/unit | E25: 9.59 | F25: 18.45 | H25: 19.16 | I25: 21.95 | J25: 24.09 | K25: =IFERROR((J25-I25)/I25,"") | L25: n/a | M25: n/a | N25: n/a | O25: n/a | P25: n/a | Q25: n/a | R25: n/a | S25: n/a | T25: n/a
A26: NDCF Payout Ratio | B26: % | C26: =IF(OR(C24="",C23="",N(C23)=0),"",C24/C23) | D26: =IF(OR(D24="",D23="",N(D23)=0),"",D24/D23) | E26: =IF(OR(E24="",E23="",N(E23)=0),"",E24/E23) | F26: =IF(OR(F24="",F23="",N(F23)=0),"",F24/F23) | G26: =IF(OR(G24="",G23="",N(G23)=0),"",G24/G23) | H26: =IF(OR(H24="",H23="",N(H23)=0),"",H24/H23) | I26: =IF(OR(I24="",I23="",N(I23)=0),"",I24/I23) | J26: =IF(OR(J24="",J23="",N(J23)=0),"",J24/J23) | L26: n/a | M26: n/a | N26: n/a | O26: n/a | P26: n/a | Q26: n/a | R26: n/a | S26: n/a | T26: n/a
A27: BALANCE SHEET & LEVERAGE
A28: Gross Asset Value (GAV) / AUM | B28: INR cr | E28: 24616.7 | F28: 26399.6 | G28: 28026.5 | H28: 29900 | I28: 36600 | J28: 49711.61 | K28: =IFERROR((J28-I28)/I28,"") | L28: n/a | M28: n/a | N28: n/a | O28: n/a | P28: n/a | Q28: n/a | R28: n/a | S28: n/a | T28: n/a
A29: Gross Debt | B29: INR cr | E29: 3606.3 | F29: 4448 | G29: 5453.5 | H29: 6972.811 | I29: 10109.782 | J29: 12976.165 | K29: =IFERROR((J29-I29)/I29,"") | N29: 1142.5 | O29: 1641.9 | Q29: 3473.601 | R29: 4615.561 | S29: 8753.529 | T29: =IFERROR((S29-R29)/R29,"")
A30: Cash & Cash Equivalents | B30: INR cr | E30: 353.9 | F30: 347.8 | G30: 406.2 | H30: 324.996 | I30: 637.931 | J30: 1217.59 | K30: =IFERROR((J30-I30)/I30,"") | N30: 293.8 | O30: 281.4 | Q30: 303.781 | R30: 28.175 | S30: 122.489 | T30: =IFERROR((S30-R30)/R30,"")
A31: Net Debt | B31: INR cr | C31: =IF(C29="","",C29-N(C30)) | D31: =IF(D29="","",D29-N(D30)) | E31: =IF(E29="","",E29-N(E30)) | F31: =IF(F29="","",F29-N(F30)) | G31: =IF(G29="","",G29-N(G30)) | H31: =IF(H29="","",H29-N(H30)) | I31: =IF(I29="","",I29-N(I30)) | J31: =IF(J29="","",J29-N(J30)) | K31: =IFERROR((J31-I31)/I31,"") | L31: =IF(L29="","",L29-N(L30)) | M31: =IF(M29="","",M29-N(M30)) | N31: =IF(N29="","",N29-N(N30)) | O31: =IF(O29="","",O29-N(O30)) | P31: =IF(P29="","",P29-N(P30)) | Q31: =IF(Q29="","",Q29-N(Q30)) | R31: =IF(R29="","",R29-N(R30)) | S31: =IF(S29="","",S29-N(S30)) | T31: =IFERROR((S31-R31)/R31,"")
A32: Net Worth / Unitholders Equity | B32: INR cr | E32: 16303 | F32: 15620.5 | H32: 14928.541 | I32: 14810.55 | J32: 15796.831 | K32: =IFERROR((J32-I32)/I32,"") | N32: 16578.9 | O32: 16575.8 | Q32: 16626.754 | R32: 16628.221 | S32: 17693.675 | T32: =IFERROR((S32-R32)/R32,"")
A33: Loan-to-Value (LTV) | B33: % | C33: =IF(OR(C31="",C28="",N(C28)=0),"",C31/C28) | D33: =IF(OR(D31="",D28="",N(D28)=0),"",D31/D28) | E33: =IF(OR(E31="",E28="",N(E28)=0),"",E31/E28) | F33: =IF(OR(F31="",F28="",N(F28)=0),"",F31/F28) | G33: =IF(OR(G31="",G28="",N(G28)=0),"",G31/G28) | H33: =IF(OR(H31="",H28="",N(H28)=0),"",H31/H28) | I33: =IF(OR(I31="",I28="",N(I28)=0),"",I31/I28) | J33: =IF(OR(J31="",J28="",N(J28)=0),"",J31/J28) | L33: =IF(OR(L31="",L28="",N(L28)=0),"",L31/L28) | M33: =IF(OR(M31="",M28="",N(M28)=0),"",M31/M28) | N33: =IF(OR(N31="",N28="",N(N28)=0),"",N31/N28) | O33: =IF(OR(O31="",O28="",N(O28)=0),"",O31/O28) | P33: =IF(OR(P31="",P28="",N(P28)=0),"",P31/P28) | Q33: =IF(OR(Q31="",Q28="",N(Q28)=0),"",Q31/Q28) | R33: =IF(OR(R31="",R28="",N(R28)=0),"",R31/R28) | S33: =IF(OR(S31="",S28="",N(S28)=0),"",S31/S28)
A34: NAV per Unit | B34: INR/unit | E34: 345.2 | F34: 364.9 | H34: 380.5 | I34: 431.7 | J34: 527.01 | K34: =IFERROR((J34-I34)/I34,"") | L34: n/a | M34: n/a | N34: n/a | O34: n/a | P34: n/a | Q34: n/a | R34: n/a | S34: n/a | T34: n/a
A35: MARKET DATA
A36: Units Outstanding | B36: mn units | E36: 593.02 | F36: 593.02 | H36: 593.02 | I36: 609.18 | J36: 648.34 | K36: =IFERROR((J36-I36)/I36,"") | L36: n/a | M36: n/a | N36: n/a | O36: n/a | P36: n/a | Q36: n/a | R36: n/a | S36: n/a | T36: n/a
A37: Unit Price (period-end) | B37: INR/unit | F37: 346.02 | G37: 325.1 | H37: 344.99 | I37: 376.99 | J37: 449 | K37: =IFERROR((J37-I37)/I37,"") | L37: n/a | M37: n/a | N37: n/a | O37: n/a | P37: n/a | Q37: n/a | R37: n/a | S37: n/a | T37: n/a
A38: Market Capitalisation | B38: INR cr | C38: =IF(OR(C36="",C37=""),"",C36*C37/10) | D38: =IF(OR(D36="",D37=""),"",D36*D37/10) | E38: =IF(OR(E36="",E37=""),"",E36*E37/10) | F38: =IF(OR(F36="",F37=""),"",F36*F37/10) | G38: =IF(OR(G36="",G37=""),"",G36*G37/10) | H38: =IF(OR(H36="",H37=""),"",H36*H37/10) | I38: =IF(OR(I36="",I37=""),"",I36*I37/10) | J38: =IF(OR(J36="",J37=""),"",J36*J37/10) | K38: =IFERROR((J38-I38)/I38,"") | L38: n/a | M38: n/a | N38: n/a | O38: n/a | P38: n/a | Q38: n/a | R38: n/a | S38: n/a | T38: n/a
A39: Annual Distribution Yield | B39: % | C39: =IF(OR(C25="",C37="",N(C37)=0),"",C25/C37) | D39: =IF(OR(D25="",D37="",N(D37)=0),"",D25/D37) | E39: =IF(OR(E25="",E37="",N(E37)=0),"",E25/E37) | F39: =IF(OR(F25="",F37="",N(F37)=0),"",F25/F37) | G39: =IF(OR(G25="",G37="",N(G37)=0),"",G25/G37) | H39: =IF(OR(H25="",H37="",N(H37)=0),"",H25/H37) | I39: =IF(OR(I25="",I37="",N(I37)=0),"",I25/I37) | J39: =IF(OR(J25="",J37="",N(J37)=0),"",J25/J37) | L39: n/a | M39: n/a | N39: n/a | O39: n/a | P39: n/a | Q39: n/a | R39: n/a | S39: n/a | T39: n/a
A40: Cost of Debt | B40: % | E40: 0.071 | F40: 0.066 | G40: 0.076 | H40: 0.078 | I40: 0.0815 | J40: 0.0741 | L40: n/a | M40: n/a | N40: n/a | O40: n/a | P40: n/a | Q40: n/a | R40: n/a | S40: n/a | T40: n/a
A41: PORTFOLIO & OPERATING METRICS (consolidated)
A42: Total Leasable Area (GLA) | B42: Msf | E42: 30.2 | F42: 31.8 | G42: 32 | H42: 33.2 | I42: 37.1 | J42: 38.2 | K42: =IFERROR((J42-I42)/I42,"") | L42: n/a | M42: n/a | N42: n/a | O42: n/a | P42: n/a | Q42: n/a | R42: n/a | S42: n/a | T42: n/a
...

Sheet Brookfield
A1: Brookfield REIT - Key Financials & Operating Metrics
A2: Sponsor: Brookfield. All INR figures in INR crore (cr) unless stated. 1 crore = 10 million. FY ends 31 March.
A3: Hover a cell for its Source (report + page + original figure). Grey italic = auto-calculated. YoY% = FY2026 vs FY2025.
C6: CONSOLIDATED | L6: STANDALONE
A7: Metric | B7: Unit | C7: FY2019 | D7: FY2020 | E7: FY2021 | F7: FY2022 | G7: FY2023 | H7: FY2024 | I7: FY2025 | J7: FY2026 | K7: YoY% | L7: FY2019 | M7: FY2020 | N7: FY2021 | O7: FY2022 | P7: FY2023 | Q7: FY2024 | R7: FY2025 | S7: FY2026 | T7: YoY%
A8: INCOME STATEMENT
A9: Revenue from Operations | B9: INR cr | E9: 130.942 | F9: 876.791 | G9: 1196.999 | H9: 1787.068 | I9: 2389.998 | J9: 2971.144 | K9: =IFERROR((J9-I9)/I9,"") | T9: =IFERROR((S9-R9)/R9,"")
A10: Other Income | B10: INR cr | E10: 5.165 | F10: 22.423 | G10: 32.48 | H10: 11.606 | I10: 81.815 | J10: 100.189 | K10: =IFERROR((J10-I10)/I10,"") | N10: 0 | O10: 12.678 | P10: 39.794 | Q10: 0.059 | R10: 219.174 | S10: 118.167 | T10: =IFERROR((S10-R10)/R10,"")
A11: Total Income | B11: INR cr | C11: =IF(AND(C9="",C10=""),"",N(C9)+N(C10)) | D11: =IF(AND(D9="",D10=""),"",N(D9)+N(D10)) | E11: =IF(AND(E9="",E10=""),"",N(E9)+N(E10)) | F11: =IF(AND(F9="",F10=""),"",N(F9)+N(F10)) | G11: =IF(AND(G9="",G10=""),"",N(G9)+N(G10)) | H11: =IF(AND(H9="",H10=""),"",N(H9)+N(H10)) | I11: =IF(AND(I9="",I10=""),"",N(I9)+N(I10)) | J11: =IF(AND(J9="",J10=""),"",N(J9)+N(J10)) | K11: =IFERROR((J11-I11)/I11,"") | L11: =IF(AND(L9="",L10=""),"",N(L9)+N(L10)) | M11: =IF(AND(M9="",M10=""),"",N(M9)+N(M10)) | N11: =IF(AND(N9="",N10=""),"",N(N9)+N(N10)) | O11: =IF(AND(O9="",O10=""),"",N(O9)+N(O10)) | P11: =IF(AND(P9="",P10=""),"",N(P9)+N(P10)) | Q11: =IF(AND(Q9="",Q10=""),"",N(Q9)+N(Q10)) | R11: =IF(AND(R9="",R10=""),"",N(R9)+N(R10)) | S11: =IF(AND(S9="",S10=""),"",N(S9)+N(S10)) | T11: =IFERROR((S11-R11)/R11,"")
A12: Property / Operating Expenses | B12: INR cr | K12: =IFERROR((J12-I12)/I12,"") | T12: =IFERROR((S12-R12)/R12,"")
A13: Net Operating Income (NOI) | B13: INR cr | E13: 660 | F13: 673 | G13: 888.5 | H13: 1350 | I13: 1854.004 | J13: 2291.299 | K13: =IFERROR((J13-I13)/I13,"") | T13: =IFERROR((S13-R13)/R13,"")
A14: NOI Margin | B14: % | C14: =IF(OR(C13="",C9="",N(C9)=0),"",C13/C9) | D14: =IF(OR(D13="",D9="",N(D9)=0),"",D13/D9) | E14: =IF(OR(E13="",E9="",N(E9)=0),"",E13/E9) | F14: =IF(OR(F13="",F9="",N(F9)=0),"",F13/F9) | G14: =IF(OR(G13="",G9="",N(G9)=0),"",G13/G9) | H14: =IF(OR(H13="",H9="",N(H9)=0),"",H13/H9) | I14: =IF(OR(I13="",I9="",N(I9)=0),"",I13/I9) | J14: =IF(OR(J13="",J9="",N(J9)=0),"",J13/J9) | L14: =IF(OR(L13="",L9="",N(L9)=0),"",L13/L9) | M14: =IF(OR(M13="",M9="",N(M9)=0),"",M13/M9) | N14: =IF(OR(N13="",N9="",N(N9)=0),"",N13/N9) | O14: =IF(OR(O13="",O9="",N(O9)=0),"",O13/O9) | P14: =IF(OR(P13="",P9="",N(P9)=0),"",P13/P9) | Q14: =IF(OR(Q13="",Q9="",N(Q9)=0),"",Q13/Q9) | R14: =IF(OR(R13="",R9="",N(R9)=0),"",R13/R9) | S14: =IF(OR(S13="",S9="",N(S9)=0),"",S13/S9)
A15: EBITDA | B15: INR cr | E15: 87.695 | F15: 640.745 | G15: 848.049 | H15: 1487.6 | I15: 1910.7 | J15: 2241.8 | K15: =IFERROR((J15-I15)/I15,"") | T15: =IFERROR((S15-R15)/R15,"")
A16: EBITDA Margin | B16: % | C16: =IF(OR(C15="",C9="",N(C9)=0),"",C15/C9) | D16: =IF(OR(D15="",D9="",N(D9)=0),"",D15/D9) | E16: =IF(OR(E15="",E9="",N(E9)=0),"",E15/E9) | F16: =IF(OR(F15="",F9="",N(F9)=0),"",F15/F9) | G16: =IF(OR(G15="",G9="",N(G9)=0),"",G15/G9) | H16: =IF(OR(H15="",H9="",N(H9)=0),"",H15/H9) | I16: =IF(OR(I15="",I9="",N(I9)=0),"",I15/I9) | J16: =IF(OR(J15="",J9="",N(J9)=0),"",J15/J9) | L16: =IF(OR(L15="",L9="",N(L9)=0),"",L15/L9) | M16: =IF(OR(M15="",M9="",N(M9)=0),"",M15/M9) | N16: =IF(OR(N15="",N9="",N(N9)=0),"",N15/N9) | O16: =IF(OR(O15="",O9="",N(O9)=0),"",O15/O9) | P16: =IF(OR(P15="",P9="",N(P9)=0),"",P15/P9) | Q16: =IF(OR(Q15="",Q9="",N(Q9)=0),"",Q15/Q9) | R16: =IF(OR(R15="",R9="",N(R9)=0),"",R15/R9) | S16: =IF(OR(S15="",S9="",N(S9)=0),"",S15/S9)
A17: Finance Costs | B17: INR cr | E17: 41.077 | F17: 208.069 | G17: 432.457 | H17: 852.245 | I17: 1078.177 | J17: 974.781 | K17: =IFERROR((J17-I17)/I17,"") | Q17: 34.479 | R17: 71.252 | S17: 110.657 | T17: =IFERROR((S17-R17)/R17,"")
A18: Depreciation & Amortisation | B18: INR cr | E18: 31.675 | F18: 208.477 | G18: 275.202 | H18: 411.209 | I18: 429.89 | J18: 469.402 | K18: =IFERROR((J18-I18)/I18,"") | T18: =IFERROR((S18-R18)/R18,"")
A19: Profit Before Tax (PBT) | B19: INR cr | E19: 14.943 | F19: 224.199 | G19: 140.39 | H19: 54.211 | I19: 249.502 | J19: 758.419 | K19: =IFERROR((J19-I19)/I19,"") | N19: 62.623 | O19: 453.702 | P19: 351.859 | Q19: 296.912 | R19: 751.498 | S19: 846.437 | T19: =IFERROR((S19-R19)/R19,"")
A20: Profit After Tax (PAT) | B20: INR cr | E20: 25.303 | F20: 246.285 | G20: 131.232 | H20: -15.35 | I20: 159.953 | J20: 536.751 | K20: =IFERROR((J20-I20)/I20,"") | N20: 62.623 | O20: 452.475 | P20: 338.808 | Q20: 298.394 | R20: 714.454 | S20: 814.876 | T20: =IFERROR((S20-R20)/R20,"")
A21: PAT Margin | B21: % | C21: =IF(OR(C20="",C9="",N(C9)=0),"",C20/C9) | D21: =IF(OR(D20="",D9="",N(D9)=0),"",D20/D9) | E21: =IF(OR(E20="",E9="",N(E9)=0),"",E20/E9) | F21: =IF(OR(F20="",F9="",N(F9)=0),"",F20/F9) | G21: =IF(OR(G20="",G9="",N(G9)=0),"",G20/G9) | H21: =IF(OR(H20="",H9="",N(H9)=0),"",H20/H9) | I21: =IF(OR(I20="",I9="",N(I9)=0),"",I20/I9) | J21: =IF(OR(J20="",J9="",N(J9)=0),"",J20/J9) | L21: =IF(OR(L20="",L9="",N(L9)=0),"",L20/L9) | M21: =IF(OR(M20="",M9="",N(M9)=0),"",M20/M9) | N21: =IF(OR(N20="",N9="",N(N9)=0),"",N20/N9) | O21: =IF(OR(O20="",O9="",N(O9)=0),"",O20/O9) | P21: =IF(OR(P20="",P9="",N(P9)=0),"",P20/P9) | Q21: =IF(OR(Q20="",Q9="",N(Q9)=0),"",Q20/Q9) | R21: =IF(OR(R20="",R9="",N(R9)=0),"",R20/R9) | S21: =IF(OR(S20="",S9="",N(S9)=0),"",S20/S9)
A22: DISTRIBUTIONS & CASH FLOW
A23: Net Distributable Cash Flow (NDCF) | B23: INR cr | F23: 688.458 | G23: 678.611 | H23: 770.52 | I23: 1055.18 | J23: 1506.695 | K23: =IFERROR((J23-I23)/I23,"") | L23: n/a | M23: n/a | N23: n/a | O23: n/a | P23: n/a | Q23: n/a | R23: n/a | S23: n/a | T23: n/a
A24: Total Distribution | B24: INR cr | F24: 740.478 | G24: 676.875 | H24: 779.4 | I24: 1053.682 | J24: 1516.178 | K24: =IFERROR((J24-I24)/I24,"") | L24: n/a | M24: n/a | N24: n/a | O24: n/a | P24: n/a | Q24: n/a | R24: n/a | S24: n/a | T24: n/a
A25: Distribution per Unit (DPU) | B25: INR/unit | F25: 22.1 | G25: 20.2 | H25: 17.75 | I25: 19.25 | J25: 21.4 | K25: =IFERROR((J25-I25)/I25,"") | L25: n/a | M25: n/a | N25: n/a | O25: n/a | P25: n/a | Q25: n/a | R25: n/a | S25: n/a | T25: n/a
A26: NDCF Payout Ratio | B26: % | C26: =IF(OR(C24="",C23="",N(C23)=0),"",C24/C23) | D26: =IF(OR(D24="",D23="",N(D23)=0),"",D24/D23) | E26: =IF(OR(E24="",E23="",N(E23)=0),"",E24/E23) | F26: =IF(OR(F24="",F23="",N(F23)=0),"",F24/F23) | G26: =IF(OR(G24="",G23="",N(G23)=0),"",G24/G23) | H26: =IF(OR(H24="",H23="",N(H23)=0),"",H24/H23) | I26: =IF(OR(I24="",I23="",N(I23)=0),"",I24/I23) | J26: =IF(OR(J24="",J23="",N(J23)=0),"",J24/J23) | L26: n/a | M26: n/a | N26: n/a | O26: n/a | P26: n/a | Q26: n/a | R26: n/a | S26: n/a | T26: n/a
A27: BALANCE SHEET & LEVERAGE
A28: Gross Asset Value (GAV) / AUM | B28: INR cr | E28: 11500 | F28: 16000 | G28: 16400 | H28: 30719.831 | I28: 34031.306 | J28: 56528.1 | K28: =IFERROR((J28-I28)/I28,"") | L28: n/a | M28: n/a | N28: n/a | O28: n/a | P28: n/a | Q28: n/a | R28: n/a | S28: n/a | T28: n/a
A29: Gross Debt | B29: INR cr | E29: 2101.517 | F29: 5165.534 | G29: 5452.038 | H29: 12112.636 | I29: 10690.03 | J29: 18130.165 | K29: =IFERROR((J29-I29)/I29,"") | N29: 0 | O29: 0 | P29: 0 | Q29: 728.487 | R29: 669.321 | S29: 2711.894 | T29: =IFERROR((S29-R29)/R29,"")
A30: Cash & Cash Equivalents | B30: INR cr | H30: 378.407 | I30: 574.649 | J30: 674.218 | K30: =IFERROR((J30-I30)/I30,"") | Q30: 239.289 | R30: 209.45 | S30: 239.311 | T30: =IFERROR((S30-R30)/R30,"")
A31: Net Debt | B31: INR cr | C31: =IF(C29="","",C29-N(C30)) | D31: =IF(D29="","",D29-N(D30)) | E31: =IF(E29="","",E29-N(E30)) | F31: =IF(F29="","",F29-N(F30)) | G31: =IF(G29="","",G29-N(G30)) | H31: =IF(H29="","",H29-N(H30)) | I31: =IF(I29="","",I29-N(I30)) | J31: =IF(J29="","",J29-N(J30)) | K31: =IFERROR((J31-I31)/I31,"") | L31: =IF(L29="","",L29-N(L30)) | M31: =IF(M29="","",M29-N(M30)) | N31: =IF(N29="","",N29-N(N30)) | O31: =IF(O29="","",O29-N(O30)) | P31: =IF(P29="","",P29-N(P30)) | Q31: =IF(Q29="","",Q29-N(Q30)) | R31: =IF(R29="","",R29-N(R30)) | S31: =IF(S29="","",S29-N(S30)) | T31: =IFERROR((S31-R31)/R31,"")
A32: Net Worth / Unitholders Equity | B32: INR cr | E32: 8202.753 | F32: 8882.093 | G32: 8333.738 | H32: 12129.66 | I32: 16010.615 | J32: 19562.123 | K32: =IFERROR((J32-I32)/I32,"") | N32: 8240.101 | O32: 9125.477 | P32: 8784.058 | Q32: 10981.584 | R32: 15414.414 | S32: 19243.162 | T32: =IFERROR((S32-R32)/R32,"")
A33: Loan-to-Value (LTV) | B33: % | C33: =IF(OR(C31="",C28="",N(C28)=0),"",C31/C28) | D33: =IF(OR(D31="",D28="",N(D28)=0),"",D31/D28) | E33: =IF(OR(E31="",E28="",N(E28)=0),"",E31/E28) | F33: =IF(OR(F31="",F28="",N(F28)=0),"",F31/F28) | G33: =IF(OR(G31="",G28="",N(G28)=0),"",G31/G28) | H33: =IF(OR(H31="",H28="",N(H28)=0),"",H31/H28) | I33: =IF(OR(I31="",I28="",N(I28)=0),"",I31/I28) | J33: =IF(OR(J31="",J28="",N(J28)=0),"",J31/J28) | L33: =IF(OR(L31="",L28="",N(L28)=0),"",L31/L28) | M33: =IF(OR(M31="",M28="",N(M28)=0),"",M31/M28) | N33: =IF(OR(N31="",N28="",N(N28)=0),"",N31/N28) | O33: =IF(OR(O31="",O28="",N(O28)=0),"",O31/O28) | P33: =IF(OR(P31="",P28="",N(P28)=0),"",P31/P28) | Q33: =IF(OR(Q31="",Q28="",N(Q28)=0),"",Q31/Q28) | R33: =IF(OR(R31="",R28="",N(R28)=0),"",R31/R28) | S33: =IF(OR(S31="",S28="",N(S28)=0),"",S31/S28)
A34: NAV per Unit | B34: INR/unit | E34: 316.59 | F34: 333.81 | G34: 332.08 | H34: 233.57 | I34: 230.85 | J34: 233.87 | K34: =IFERROR((J34-I34)/I34,"") | L34: n/a | M34: n/a | N34: n/a | O34: n/a | P34: n/a | Q34: n/a | R34: n/a | S34: n/a | T34: n/a
A35: MARKET DATA
A36: Units Outstanding | B36: mn units | E36: 302801601 | F36: 335087073 | G36: 335087073 | H36: 439.09 | I36: 607.75 | J36: 749.39 | K36: =IFERROR((J36-I36)/I36,"") | L36: n/a | M36: n/a | N36: n/a | O36: n/a | P36: n/a | Q36: n/a | R36: n/a | S36: n/a | T36: n/a
A37: Unit Price (period-end) | B37: INR/unit | F37: 310.21 | G37: 279.9 | H37: 253.25 | I37: 290 | J37: 320.31 | K37: =IFERROR((J37-I37)/I37,"") | L37: n/a | M37: n/a | N37: n/a | O37: n/a | P37: n/a | Q37: n/a | R37: n/a | S37: n/a | T37: n/a
A38: Market Capitalisation | B38: INR cr | C38: =IF(OR(C36="",C37=""),"",C36*C37/10) | D38: =IF(OR(D36="",D37=""),"",D36*D37/10) | E38: =IF(OR(E36="",E37=""),"",E36*E37/10) | F38: =IF(OR(F36="",F37=""),"",F36*F37/10) | G38: =IF(OR(G36="",G37=""),"",G36*G37/10) | H38: =IF(OR(H36="",H37=""),"",H36*H37/10) | I38: =IF(OR(I36="",I37=""),"",I36*I37/10) | J38: =IF(OR(J36="",J37=""),"",J36*J37/10) | K38: =IFERROR((J38-I38)/I38,"") | L38: n/a | M38: n/a | N38: n/a | O38: n/a | P38: n/a | Q38: n/a | R38: n/a | S38: n/a | T38: n/a
A39: Annual Distribution Yield | B39: % | C39: =IF(OR(C25="",C37="",N(C37)=0),"",C25/C37) | D39: =IF(OR(D25="",D37="",N(D37)=0),"",D25/D37) | E39: =IF(OR(E25="",E37="",N(E37)=0),"",E25/E37) | F39: =IF(OR(F25="",F37="",N(F37)=0),"",F25/F37) | G39: =IF(OR(G25="",G37="",N(G37)=0),"",G25/G37) | H39: =IF(OR(H25="",H37="",N(H37)=0),"",H25/H37) | I39: =IF(OR(I25="",I37="",N(I37)=0),"",I25/I37) | J39: =IF(OR(J25="",J37="",N(J37)=0),"",J25/J37) | L39: n/a | M39: n/a | N39: n/a | O39: n/a | P39: n/a | Q39: n/a | R39: n/a | S39: n/a | T39: n/a
A40: Cost of Debt | B40: % | E40: 0.0715 | F40: 0.0676 | G40: 0.082 | H40: 0.083 | I40: 0.082 | J40: 0.0805 | L40: n/a | M40: n/a | N40: n/a | O40: n/a | P40: n/a | Q40: n/a | R40: n/a | S40: n/a | T40: n/a
A41: PORTFOLIO & OPERATING METRICS (consolidated)
A42: Total Leasable Area (GLA) | B42: Msf | E42: 14 | F42: 18.6 | G42: 18.7 | H42: 25.5 | I42: 29 | J42: 32.43 | K42: =IFERROR((J42-I42)/I42,"") | L42: n/a | M42: n/a | N42: n/a | O42: n/a | P42: n/a | Q42: n/a | R42: n/a | S42: n/a | T42: n/a
...

Sheet Nexus
A1: Nexus REIT - Key Financials & Operating Metrics
A2: Sponsor: Blackstone (Retail REIT). All INR figures in INR crore (cr) unless stated. 1 crore = 10 million. FY ends 31 March.
A3: Hover a cell for its Source (report + page + original figure). Grey italic = auto-calculated. YoY% = FY2026 vs FY2025.
C6: CONSOLIDATED | L6: STANDALONE
A7: Metric | B7: Unit | C7: FY2019 | D7: FY2020 | E7: FY2021 | F7: FY2022 | G7: FY2023 | H7: FY2024 | I7: FY2025 | J7: FY2026 | K7: YoY% | L7: FY2019 | M7: FY2020 | N7: FY2021 | O7: FY2022 | P7: FY2023 | Q7: FY2024 | R7: FY2025 | S7: FY2026 | T7: YoY%
A8: INCOME STATEMENT
A9: Revenue from Operations | B9: INR cr | H9: 1916.374 | I9: 2282.89 | J9: 2568 | K9: =IFERROR((J9-I9)/I9,"") | T9: =IFERROR((S9-R9)/R9,"")
A10: Other Income | B10: INR cr | H10: 80.737 | I10: 116.52 | J10: 87.3 | K10: =IFERROR((J10-I10)/I10,"") | Q10: 6.947 | R10: 14.87 | S10: 5.24 | T10: =IFERROR((S10-R10)/R10,"")
A11: Total Income | B11: INR cr | C11: =IF(AND(C9="",C10=""),"",N(C9)+N(C10)) | D11: =IF(AND(D9="",D10=""),"",N(D9)+N(D10)) | E11: =IF(AND(E9="",E10=""),"",N(E9)+N(E10)) | F11: =IF(AND(F9="",F10=""),"",N(F9)+N(F10)) | G11: =IF(AND(G9="",G10=""),"",N(G9)+N(G10)) | H11: =IF(AND(H9="",H10=""),"",N(H9)+N(H10)) | I11: =IF(AND(I9="",I10=""),"",N(I9)+N(I10)) | J11: =IF(AND(J9="",J10=""),"",N(J9)+N(J10)) | K11: =IFERROR((J11-I11)/I11,"") | L11: =IF(AND(L9="",L10=""),"",N(L9)+N(L10)) | M11: =IF(AND(M9="",M10=""),"",N(M9)+N(M10)) | N11: =IF(AND(N9="",N10=""),"",N(N9)+N(N10)) | O11: =IF(AND(O9="",O10=""),"",N(O9)+N(O10)) | P11: =IF(AND(P9="",P10=""),"",N(P9)+N(P10)) | Q11: =IF(AND(Q9="",Q10=""),"",N(Q9)+N(Q10)) | R11: =IF(AND(R9="",R10=""),"",N(R9)+N(R10)) | S11: =IF(AND(S9="",S10=""),"",N(S9)+N(S10)) | T11: =IFERROR((S11-R11)/R11,"")
A12: Property / Operating Expenses | B12: INR cr | H12: 166.227 | I12: 387.06 | J12: 428.43 | K12: =IFERROR((J12-I12)/I12,"") | R12: 12.62 | S12: 13.66 | T12: =IFERROR((S12-R12)/R12,"")
A13: Net Operating Income (NOI) | B13: INR cr | H13: 1434.788 | I13: 1711.03 | J13: 1929.64 | K13: =IFERROR((J13-I13)/I13,"") | T13: =IFERROR((S13-R13)/R13,"")
A14: NOI Margin | B14: % | C14: =IF(OR(C13="",C9="",N(C9)=0),"",C13/C9) | D14: =IF(OR(D13="",D9="",N(D9)=0),"",D13/D9) | E14: =IF(OR(E13="",E9="",N(E9)=0),"",E13/E9) | F14: =IF(OR(F13="",F9="",N(F9)=0),"",F13/F9) | G14: =IF(OR(G13="",G9="",N(G9)=0),"",G13/G9) | H14: =IF(OR(H13="",H9="",N(H9)=0),"",H13/H9) | I14: =IF(OR(I13="",I9="",N(I9)=0),"",I13/I9) | J14: =IF(OR(J13="",J9="",N(J9)=0),"",J13/J9) | L14: =IF(OR(L13="",L9="",N(L9)=0),"",L13/L9) | M14: =IF(OR(M13="",M9="",N(M9)=0),"",M13/M9) | N14: =IF(OR(N13="",N9="",N(N9)=0),"",N13/N9) | O14: =IF(OR(O13="",O9="",N(O9)=0),"",O13/O9) | P14: =IF(OR(P13="",P9="",N(P9)=0),"",P13/P9) | Q14: =IF(OR(Q13="",Q9="",N(Q9)=0),"",Q13/Q9) | R14: =IF(OR(R13="",R9="",N(R9)=0),"",R13/R9) | S14: =IF(OR(S13="",S9="",N(S9)=0),"",S13/S9)
A15: EBITDA | B15: INR cr | H15: 1365.778 | I15: 1660.76 | J15: 1820.73 | K15: =IFERROR((J15-I15)/I15,"") | Q15: 1046.081 | R15: 1307.16 | S15: 1485.44 | T15: =IFERROR((S15-R15)/R15,"")
A16: EBITDA Margin | B16: % | C16: =IF(OR(C15="",C9="",N(C9)=0),"",C15/C9) | D16: =IF(OR(D15="",D9="",N(D9)=0),"",D15/D9) | E16: =IF(OR(E15="",E9="",N(E9)=0),"",E15/E9) | F16: =IF(OR(F15="",F9="",N(F9)=0),"",F15/F9) | G16: =IF(OR(G15="",G9="",N(G9)=0),"",G15/G9) | H16: =IF(OR(H15="",H9="",N(H9)=0),"",H15/H9) | I16: =IF(OR(I15="",I9="",N(I9)=0),"",I15/I9) | J16: =IF(OR(J15="",J9="",N(J9)=0),"",J15/J9) | L16: =IF(OR(L15="",L9="",N(L9)=0),"",L15/L9) | M16: =IF(OR(M15="",M9="",N(M9)=0),"",M15/M9) | N16: =IF(OR(N15="",N9="",N(N9)=0),"",N15/N9) | O16: =IF(OR(O15="",O9="",N(O9)=0),"",O15/O9) | P16: =IF(OR(P15="",P9="",N(P9)=0),"",P15/P9) | Q16: =IF(OR(Q15="",Q9="",N(Q9)=0),"",Q15/Q9) | R16: =IF(OR(R15="",R9="",N(R9)=0),"",R15/R9) | S16: =IF(OR(S15="",S9="",N(S9)=0),"",S15/S9)
A17: Finance Costs | B17: INR cr | H17: 337.095 | I17: 394.34 | J17: 457.95 | K17: =IFERROR((J17-I17)/I17,"") | Q17: 150.091 | R17: 234.51 | S17: 316.22 | T17: =IFERROR((S17-R17)/R17,"")
A18: Depreciation & Amortisation | B18: INR cr | H18: 570.164 | I18: 586.12 | J18: 619.84 | K18: =IFERROR((J18-I18)/I18,"") | T18: =IFERROR((S18-R18)/R18,"")
A19: Profit Before Tax (PBT) | B19: INR cr | H19: 514.775 | I19: 697.85 | J19: 743.29 | K19: =IFERROR((J19-I19)/I19,"") | Q19: 895.99 | R19: 1072.65 | S19: 1169.22 | T19: =IFERROR((S19-R19)/R19,"")
A20: Profit After Tax (PAT) | B20: INR cr | H20: 597.846 | I20: 482.81 | J20: 403.47 | K20: =IFERROR((J20-I20)/I20,"") | Q20: 893.91 | R20: 1069.01 | S20: 1168.43 | T20: =IFERROR((S20-R20)/R20,"")
A21: PAT Margin | B21: % | C21: =IF(OR(C20="",C9="",N(C9)=0),"",C20/C9) | D21: =IF(OR(D20="",D9="",N(D9)=0),"",D20/D9) | E21: =IF(OR(E20="",E9="",N(E9)=0),"",E20/E9) | F21: =IF(OR(F20="",F9="",N(F9)=0),"",F20/F9) | G21: =IF(OR(G20="",G9="",N(G9)=0),"",G20/G9) | H21: =IF(OR(H20="",H9="",N(H9)=0),"",H20/H9) | I21: =IF(OR(I20="",I9="",N(I9)=0),"",I20/I9) | J21: =IF(OR(J20="",J9="",N(J9)=0),"",J20/J9) | L21: =IF(OR(L20="",L9="",N(L9)=0),"",L20/L9) | M21: =IF(OR(M20="",M9="",N(M9)=0),"",M20/M9) | N21: =IF(OR(N20="",N9="",N(N9)=0),"",N20/N9) | O21: =IF(OR(O20="",O9="",N(O9)=0),"",O20/O9) | P21: =IF(OR(P20="",P9="",N(P9)=0),"",P20/P9) | Q21: =IF(OR(Q20="",Q9="",N(Q9)=0),"",Q20/Q9) | R21: =IF(OR(R20="",R9="",N(R9)=0),"",R20/R9) | S21: =IF(OR(S20="",S9="",N(S9)=0),"",S20/S9)
A22: DISTRIBUTIONS & CASH FLOW
A23: Net Distributable Cash Flow (NDCF) | B23: INR cr | H23: 1071.863 | I23: 1190.48 | J23: 1279.32 | K23: =IFERROR((J23-I23)/I23,"") | L23: n/a | M23: n/a | N23: n/a | O23: n/a | P23: n/a | Q23: n/a | R23: n/a | S23: n/a | T23: n/a
A24: Total Distribution | B24: INR cr | H24: 755.076 | I24: 1234.725 | J24: 1375.77 | K24: =IFERROR((J24-I24)/I24,"") | L24: n/a | M24: n/a | N24: n/a | O24: n/a | P24: n/a | Q24: n/a | R24: n/a | S24: n/a | T24: n/a
A25: Distribution per Unit (DPU) | B25: INR/unit | H25: 4.99 | I25: 8.15 | J25: 9.08 | K25: =IFERROR((J25-I25)/I25,"") | L25: n/a | M25: n/a | N25: n/a | O25: n/a | P25: n/a | Q25: n/a | R25: n/a | S25: n/a | T25: n/a
A26: NDCF Payout Ratio | B26: % | C26: =IF(OR(C24="",C23="",N(C23)=0),"",C24/C23) | D26: =IF(OR(D24="",D23="",N(D23)=0),"",D24/D23) | E26: =IF(OR(E24="",E23="",N(E23)=0),"",E24/E23) | F26: =IF(OR(F24="",F23="",N(F23)=0),"",F24/F23) | G26: =IF(OR(G24="",G23="",N(G23)=0),"",G24/G23) | H26: =IF(OR(H24="",H23="",N(H23)=0),"",H24/H23) | I26: =IF(OR(I24="",I23="",N(I23)=0),"",I24/I23) | J26: =IF(OR(J24="",J23="",N(J23)=0),"",J24/J23) | L26: n/a | M26: n/a | N26: n/a | O26: n/a | P26: n/a | Q26: n/a | R26: n/a | S26: n/a | T26: n/a
A27: BALANCE SHEET & LEVERAGE
A28: Gross Asset Value (GAV) / AUM | B28: INR cr | H28: 27083.693 | I28: 29411.332 | J28: 30558.3 | K28: =IFERROR((J28-I28)/I28,"") | L28: n/a | M28: n/a | N28: n/a | O28: n/a | P28: n/a | Q28: n/a | R28: n/a | S28: n/a | T28: n/a
A29: Gross Debt | B29: INR cr | H29: 4263.531 | I29: 5328.55 | J29: 6197.23 | K29: =IFERROR((J29-I29)/I29,"") | Q29: 7224.537 | R29: 3521.13 | S29: 4384.91 | T29: =IFERROR((S29-R29)/R29,"")
A30: Cash & Cash Equivalents | B30: INR cr | H30: 39.404 | I30: 19.3 | J30: 36.03 | K30: =IFERROR((J30-I30)/I30,"") | Q30: 52.016 | R30: 7.72 | S30: 23.11 | T30: =IFERROR((S30-R30)/R30,"")
A31: Net Debt | B31: INR cr | C31: =IF(C29="","",C29-N(C30)) | D31: =IF(D29="","",D29-N(D30)) | E31: =IF(E29="","",E29-N(E30)) | F31: =IF(F29="","",F29-N(F30)) | G31: =IF(G29="","",G29-N(G30)) | H31: =IF(H29="","",H29-N(H30)) | I31: =IF(I29="","",I29-N(I30)) | J31: =IF(J29="","",J29-N(J30)) | K31: =IFERROR((J31-I31)/I31,"") | L31: =IF(L29="","",L29-N(L30)) | M31: =IF(M29="","",M29-N(M30)) | N31: =IF(N29="","",N29-N(N30)) | O31: =IF(O29="","",O29-N(O30)) | P31: =IF(P29="","",P29-N(P30)) | Q31: =IF(Q29="","",Q29-N(Q30)) | R31: =IF(R29="","",R29-N(R30)) | S31: =IF(S29="","",S29-N(S30)) | T31: =IFERROR((S31-R31)/R31,"")
A32: Net Worth / Unitholders Equity | B32: INR cr | H32: 14934.85 | I32: 14138.66 | J32: 13210.1 | K32: =IFERROR((J32-I32)/I32,"") | Q32: 15230.914 | R32: 15021.11 | S32: 14857.09 | T32: =IFERROR((S32-R32)/R32,"")
A33: Loan-to-Value (LTV) | B33: % | C33: =IF(OR(C31="",C28="",N(C28)=0),"",C31/C28) | D33: =IF(OR(D31="",D28="",N(D28)=0),"",D31/D28) | E33: =IF(OR(E31="",E28="",N(E28)=0),"",E31/E28) | F33: =IF(OR(F31="",F28="",N(F28)=0),"",F31/F28) | G33: =IF(OR(G31="",G28="",N(G28)=0),"",G31/G28) | H33: =IF(OR(H31="",H28="",N(H28)=0),"",H31/H28) | I33: =IF(OR(I31="",I28="",N(I28)=0),"",I31/I28) | J33: =IF(OR(J31="",J28="",N(J28)=0),"",J31/J28) | L33: =IF(OR(L31="",L28="",N(L28)=0),"",L31/L28) | M33: =IF(OR(M31="",M28="",N(M28)=0),"",M31/M28) | N33: =IF(OR(N31="",N28="",N(N28)=0),"",N31/N28) | O33: =IF(OR(O31="",O28="",N(O28)=0),"",O31/O28) | P33: =IF(OR(P31="",P28="",N(P28)=0),"",P31/P28) | Q33: =IF(OR(Q31="",Q28="",N(Q28)=0),"",Q31/Q28) | R33: =IF(OR(R31="",R28="",N(R28)=0),"",R31/R28) | S33: =IF(OR(S31="",S28="",N(S28)=0),"",S31/S28)
A34: NAV per Unit | B34: INR/unit | H34: 98.58 | I34: 93.32 | J34: 87.7 | K34: =IFERROR((J34-I34)/I34,"") | L34: n/a | M34: n/a | N34: n/a | O34: n/a | P34: n/a | Q34: n/a | R34: n/a | S34: n/a | T34: n/a
A35: MARKET DATA
A36: Units Outstanding | B36: mn units | H36: 1515 | I36: 1515 | J36: 1515 | K36: =IFERROR((J36-I36)/I36,"") | L36: n/a | M36: n/a | N36: n/a | O36: n/a | P36: n/a | Q36: n/a | R36: n/a | S36: n/a | T36: n/a
A37: Unit Price (period-end) | B37: INR/unit | H37: 128 | I37: 130.5 | J37: 151 | K37: =IFERROR((J37-I37)/I37,"") | L37: n/a | M37: n/a | N37: n/a | O37: n/a | P37: n/a | Q37: n/a | R37: n/a | S37: n/a | T37: n/a
A38: Market Capitalisation | B38: INR cr | C38: =IF(OR(C36="",C37=""),"",C36*C37/10) | D38: =IF(OR(D36="",D37=""),"",D36*D37/10) | E38: =IF(OR(E36="",E37=""),"",E36*E37/10) | F38: =IF(OR(F36="",F37=""),"",F36*F37/10) | G38: =IF(OR(G36="",G37=""),"",G36*G37/10) | H38: =IF(OR(H36="",H37=""),"",H36*H37/10) | I38: =IF(OR(I36="",I37=""),"",I36*I37/10) | J38: =IF(OR(J36="",J37=""),"",J36*J37/10) | K38: =IFERROR((J38-I38)/I38,"") | L38: n/a | M38: n/a | N38: n/a | O38: n/a | P38: n/a | Q38: n/a | R38: n/a | S38: n/a | T38: n/a
A39: Annual Distribution Yield | B39: % | C39: =IF(OR(C25="",C37="",N(C37)=0),"",C25/C37) | D39: =IF(OR(D25="",D37="",N(D37)=0),"",D25/D37) | E39: =IF(OR(E25="",E37="",N(E37)=0),"",E25/E37) | F39: =IF(OR(F25="",F37="",N(F37)=0),"",F25/F37) | G39: =IF(OR(G25="",G37="",N(G37)=0),"",G25/G37) | H39: =IF(OR(H25="",H37="",N(H37)=0),"",H25/H37) | I39: =IF(OR(I25="",I37="",N(I37)=0),"",I25/I37) | J39: =IF(OR(J25="",J37="",N(J37)=0),"",J25/J37) | L39: n/a | M39: n/a | N39: n/a | O39: n/a | P39: n/a | Q39: n/a | R39: n/a | S39: n/a | T39: n/a
A40: Cost of Debt | B40: % | H40: 0.08 | I40: 0.08 | J40: 0.075 | L40: n/a | M40: n/a | N40: n/a | O40: n/a | P40: n/a | Q40: n/a | R40: n/a | S40: n/a | T40: n/a
A41: PORTFOLIO & OPERATING METRICS (consolidated)
A42: Total Leasable Area (GLA) | B42: Msf | H42: 9.9 | I42: 10.4 | J42: 11.9 | K42: =IFERROR((J42-I42)/I42,"") | L42: n/a | M42: n/a | N42: n/a | O42: n/a | P42: n/a | Q42: n/a | R42: n/a | S42: n/a | T42: n/a
...

Sheet Knowledge (KRT)
A1: Knowledge Realty Trust (KRT) - Key Financials & Operating Metrics
A2: Sponsor: Sattva Group / Blackstone. All INR figures in INR crore (cr) unless stated. 1 crore = 10 million. FY ends 31 March.
A3: Hover a cell for its Source (report + page + original figure). Grey italic = auto-calculated. YoY% = FY2026 vs FY2025.
C6: CONSOLIDATED | L6: STANDALONE
A7: Metric | B7: Unit | C7: FY2019 | D7: FY2020 | E7: FY2021 | F7: FY2022 | G7: FY2023 | H7: FY2024 | I7: FY2025 | J7: FY2026 | K7: YoY% | L7: FY2019 | M7: FY2020 | N7: FY2021 | O7: FY2022 | P7: FY2023 | Q7: FY2024 | R7: FY2025 | S7: FY2026 | T7: YoY%
A8: INCOME STATEMENT
A9: Revenue from Operations | B9: INR cr | I9: 0 | J9: 3046.628 | K9: =IFERROR((J9-I9)/I9,"") | T9: =IFERROR((S9-R9)/R9,"")
A10: Other Income | B10: INR cr | J10: 43.982 | K10: =IFERROR((J10-I10)/I10,"") | S10: 7.2 | T10: =IFERROR((S10-R10)/R10,"")
A11: Total Income | B11: INR cr | C11: =IF(AND(C9="",C10=""),"",N(C9)+N(C10)) | D11: =IF(AND(D9="",D10=""),"",N(D9)+N(D10)) | E11: =IF(AND(E9="",E10=""),"",N(E9)+N(E10)) | F11: =IF(AND(F9="",F10=""),"",N(F9)+N(F10)) | G11: =IF(AND(G9="",G10=""),"",N(G9)+N(G10)) | H11: =IF(AND(H9="",H10=""),"",N(H9)+N(H10)) | I11: =IF(AND(I9="",I10=""),"",N(I9)+N(I10)) | J11: =IF(AND(J9="",J10=""),"",N(J9)+N(J10)) | K11: =IFERROR((J11-I11)/I11,"") | L11: =IF(AND(L9="",L10=""),"",N(L9)+N(L10)) | M11: =IF(AND(M9="",M10=""),"",N(M9)+N(M10)) | N11: =IF(AND(N9="",N10=""),"",N(N9)+N(N10)) | O11: =IF(AND(O9="",O10=""),"",N(O9)+N(O10)) | P11: =IF(AND(P9="",P10=""),"",N(P9)+N(P10)) | Q11: =IF(AND(Q9="",Q10=""),"",N(Q9)+N(Q10)) | R11: =IF(AND(R9="",R10=""),"",N(R9)+N(R10)) | S11: =IF(AND(S9="",S10=""),"",N(S9)+N(S10)) | T11: =IFERROR((S11-R11)/R11,"")
A12: Property / Operating Expenses | B12: INR cr | J12: 271.098 | K12: =IFERROR((J12-I12)/I12,"") | T12: =IFERROR((S12-R12)/R12,"")
A13: Net Operating Income (NOI) | B13: INR cr | J13: 2694.076 | K13: =IFERROR((J13-I13)/I13,"") | T13: =IFERROR((S13-R13)/R13,"")
A14: NOI Margin | B14: % | C14: =IF(OR(C13="",C9="",N(C9)=0),"",C13/C9) | D14: =IF(OR(D13="",D9="",N(D9)=0),"",D13/D9) | E14: =IF(OR(E13="",E9="",N(E9)=0),"",E13/E9) | F14: =IF(OR(F13="",F9="",N(F9)=0),"",F13/F9) | G14: =IF(OR(G13="",G9="",N(G9)=0),"",G13/G9) | H14: =IF(OR(H13="",H9="",N(H9)=0),"",H13/H9) | I14: =IF(OR(I13="",I9="",N(I9)=0),"",I13/I9) | J14: =IF(OR(J13="",J9="",N(J9)=0),"",J13/J9) | L14: =IF(OR(L13="",L9="",N(L9)=0),"",L13/L9) | M14: =IF(OR(M13="",M9="",N(M9)=0),"",M13/M9) | N14: =IF(OR(N13="",N9="",N(N9)=0),"",N13/N9) | O14: =IF(OR(O13="",O9="",N(O9)=0),"",O13/O9) | P14: =IF(OR(P13="",P9="",N(P9)=0),"",P13/P9) | Q14: =IF(OR(Q13="",Q9="",N(Q9)=0),"",Q13/Q9) | R14: =IF(OR(R13="",R9="",N(R9)=0),"",R13/R9) | S14: =IF(OR(S13="",S9="",N(S9)=0),"",S13/S9)
A15: EBITDA | B15: INR cr | J15: 2532.579 | K15: =IFERROR((J15-I15)/I15,"") | S15: 2519.71 | T15: =IFERROR((S15-R15)/R15,"")
A16: EBITDA Margin | B16: % | C16: =IF(OR(C15="",C9="",N(C9)=0),"",C15/C9) | D16: =IF(OR(D15="",D9="",N(D9)=0),"",D15/D9) | E16: =IF(OR(E15="",E9="",N(E9)=0),"",E15/E9) | F16: =IF(OR(F15="",F9="",N(F9)=0),"",F15/F9) | G16: =IF(OR(G15="",G9="",N(G9)=0),"",G15/G9) | H16: =IF(OR(H15="",H9="",N(H9)=0),"",H15/H9) | I16: =IF(OR(I15="",I9="",N(I9)=0),"",I15/I9) | J16: =IF(OR(J15="",J9="",N(J9)=0),"",J15/J9) | L16: =IF(OR(L15="",L9="",N(L9)=0),"",L15/L9) | M16: =IF(OR(M15="",M9="",N(M9)=0),"",M15/M9) | N16: =IF(OR(N15="",N9="",N(N9)=0),"",N15/N9) | O16: =IF(OR(O15="",O9="",N(O9)=0),"",O15/O9) | P16: =IF(OR(P15="",P9="",N(P9)=0),"",P15/P9) | Q16: =IF(OR(Q15="",Q9="",N(Q9)=0),"",Q15/Q9) | R16: =IF(OR(R15="",R9="",N(R9)=0),"",R15/R9) | S16: =IF(OR(S15="",S9="",N(S9)=0),"",S15/S9)
A17: Finance Costs | B17: INR cr | J17: 681.952 | K17: =IFERROR((J17-I17)/I17,"") | S17: 128.154 | T17: =IFERROR((S17-R17)/R17,"")
A18: Depreciation & Amortisation | B18: INR cr | J18: 1050.479 | K18: =IFERROR((J18-I18)/I18,"") | S18: 0 | T18: =IFERROR((S18-R18)/R18,"")
