Workbook

Sheet Summary
A1: Market | B1: Avg div yield — top 3 REITs | C1: Office: avg yield (paying) | D1: Office: median yield (paying) | E1: Office REITs (paying / listed) | F1: Sector mkt cap (US$ bn) | G1: % of Global REIT Index | H1: Top-3 share of sector
A2: India | B2: ='Top 3 REITs'!F5 -> 0.053066667 | C2: ='Office REITs'!F8 -> 0.05615 | D2: ='Office REITs'!F9 -> 0.0539 | E2: 4 / 5
A3: USA | B3: ='Top 3 REITs'!F10 -> 0.021133333 | C3: ='Office REITs'!F31 -> 0.05492 | D3: ='Office REITs'!F32 -> 0.0565 | E3: 15 / 19
A4: Japan | B4: ='Top 3 REITs'!F15 -> 0.042633333 | C4: ='Office REITs'!F41 -> 0.05515 | D4: ='Office REITs'!F42 -> 0.04365 | E4: 6 / 6
A5: Australia | B5: ='Top 3 REITs'!F20 -> 0.035066667 | C5: ='Office REITs'!F49 -> 0.08095 | D5: ='Office REITs'!F50 -> 0.0751 | E5: 4 / 4
A6: Singapore | B6: ='Top 3 REITs'!F25 -> 0.058366667 | C6: ='Office REITs'!F60 -> 0.050633333 | D6: ='Office REITs'!F61 -> 0.0526 | E6: 6 / 7
A7: UK | B7: ='Top 3 REITs'!F30 -> 0.0559 | C7: ='Office REITs'!F69 -> 0.05186 | D7: ='Office REITs'!F70 -> 0.0409 | E7: 5 / 5 | F7: 80 | G7: 0.036 | H7: =(10.15+4.78+3.96)/60 -> 0.31483333
A8: Hong Kong | B8: ='Top 3 REITs'!F35 -> 0.066433333 | C8: ='Office REITs'!F77 -> 0.07 | D8: ='Office REITs'!F78 -> 0.07025 | E8: 4 / 4
A9: Malaysia | B9: ='Top 3 REITs'!F40 -> 0.0533 | C9: ='Office REITs'!F86 -> 0.07406 | D9: ='Office REITs'!F87 -> 0.0848 | E9: 5 / 5 | F9: 15 | G9: 0.002 | H9: =(16.14+12.03+7.6)/63.89 -> 0.55986852
A11: Yields = trailing-twelve-month distributions / delayed price, stockanalysis.com (S&P Global), retrieved 10-11 Jul 2026.
A12: Top 3 = three largest REITs by market cap per market (India: largest dividend-paying; Bagmane pre-first-distribution excluded).
A13: Office columns link to the 'Office REITs' sheet; suspended payers (US: PDM, HPP, CMCT; SG: Manulife US) and NLOP (liquidating) excluded from stats.
A14: Blue cells are hardcoded estimates: UK sector cap ~GBP60bn ~US$80bn (ValueWalk/UK-REIT data); Malaysia RM63.9bn ~US$15bn (The Edge, Feb 2026);
A15: index weights = FTSE EPRA Nareit Global REITs proxy via iShares REET country breakdown (UK 3.6%); Malaysia ~0.2% is a free-float estimate (gated FTSE factsheet).
A16: Top-3 share formulas: UK = (SEGRO+LandSec+British Land)/GBP60bn; Malaysia = (KLCC+IGB+Sunway)/RM63.89bn (Feb-2026 sector total vs Jun-2026 mcaps).

Sheet Office REITs
A1: Country | B1: Ticker | C1: Name | D1: Market cap (bn, local ccy) | E1: Ccy | F1: TTM div yield | G1: Notes / flags
A2: India
B3: EMBASSY | C3: Embassy Office Parks REIT | D3: 425.95 | E3: INR | F3: 0.0514
B4: MINDSPACE | C4: Mindspace Business Parks REIT | D4: 305.43 | E4: INR | F4: 0.0523
B5: BIRET | C5: Brookfield India Real Estate Trust | D5: 280.23 | E5: INR | F5: 0.0654
B6: KRT | C6: Knowledge Realty Trust | D6: 516.56 | E6: INR | F6: 0.0555 | G6: listed Aug 2025; partial-year TTM
B7: BAGMANE | C7: Bagmane Prime Office REIT | D7: 351.8 | E7: INR | F7: n/a | G7: no distribution yet (listed 2026) — excluded
C8: Average — paying office REITs (4) | F8: =AVERAGE(F3:F6) -> 0.05615
C9: Median — paying office REITs (4) | F9: =MEDIAN(F3:F6) -> 0.0539
A11: USA
B12: BXP | C12: BXP, Inc. | D12: 12.36 | E12: US$ | F12: 0.0404
B13: ARE | C13: Alexandria Real Estate Equities | D13: 9.16 | E13: US$ | F13: 0.0956
B14: VNO | C14: Vornado Realty Trust | D14: 8.32 | E14: US$ | F14: 0.0182
B15: CUZ | C15: Cousins Properties | D15: 5.11 | E15: US$ | F15: 0.0454
B16: KRC | C16: Kilroy Realty | D16: 4.62 | E16: US$ | F16: 0.0565
B17: CDP | C17: COPT Defense Properties | D17: 4.34 | E17: US$ | F17: 0.0379
B18: SLG | C18: SL Green Realty | D18: 4.11 | E18: US$ | F18: 0.0636
B19: HIW | C19: Highwoods Properties | D19: 3.58 | E19: US$ | F19: 0.0691
B20: DEI | C20: Douglas Emmett | D20: 2.57 | E20: US$ | F20: 0.0663
B21: ESBA | C21: Empire State Realty OP | D21: 1.6 | E21: US$ | F21: 0.0247 | G21: OP units of ESRT
B22: DEA | C22: Easterly Government Properties | D22: 1.31 | E22: US$ | F22: 0.0762
B23: PSTL | C23: Postal Realty Trust | D23: 0.87 | E23: US$ | F23: 0.0395
B24: BDN | C24: Brandywine Realty Trust | D24: 0.56 | E24: US$ | F24: 0.1041
B25: ONL | C25: Orion Properties | D25: 0.16 | E25: US$ | F25: 0.0275
B26: FSP | C26: Franklin Street Properties | D26: 0.05 | E26: US$ | F26: 0.0588 | G26: token $0.01/qtr; strategic review
B27: PDM | C27: Piedmont Realty Trust | D27: 1.2 | E27: US$ | F27: 0 | G27: SUSPENDED (last paid Mar 2025) — excluded from stats
B28: HPP | C28: Hudson Pacific Properties | D28: 0.94 | E28: US$ | F28: 0 | G28: SUSPENDED common since mid-2024 — excluded from stats
B29: CMCT | C29: Creative Media & Community Trust | D29: 0.01 | E29: US$ | F29: 0 | G29: no common dividend — excluded from stats
B30: NLOP | C30: Net Lease Office Properties | D30: 0.17 | E30: US$ | F30: n/a | G30: LIQUIDATING; 'yield' ~201% = return of capital — excluded
C31: Average — paying office REITs (15) | F31: =AVERAGE(F12:F26) -> 0.05492
C32: Median — paying office REITs (15) | F32: =MEDIAN(F12:F26) -> 0.0565
A34: Japan
B35: 8951 | C35: Nippon Building Fund | D35: 1050 | E35: JPY | F35: 0.0412
B36: 8952 | C36: Japan Real Estate Investment | D36: 868.2 | E36: JPY | F36: 0.0432
B37: 8976 | C37: Daiwa Office Investment | D37: 309.9 | E37: JPY | F37: 0.0432
B38: 8987 | C38: Japan Excellent | D38: 179.6 | E38: JPY | F38: 0.0441
B39: 8975 | C39: Ichigo Office REIT | D39: 138 | E39: JPY | F39: 0.0844 | G39: payout boosted by gains on sale
B40: 8958 | C40: Global One Real Estate | D40: 118.5 | E40: JPY | F40: 0.0748 | G40: payout boosted by gains on sale
C41: Average — paying office REITs (6) | F41: =AVERAGE(F35:F40) -> 0.05515
C42: Median — paying office REITs (6) | F42: =MEDIAN(F35:F40) -> 0.04365
...

Sheet Top 3 REITs
A1: Country | B1: Ticker | C1: Name | D1: Market cap (bn, local ccy) | E1: Ccy | F1: TTM div yield | G1: Notes
A2: India | B2: KRT | C2: Knowledge Realty Trust | D2: 516.56 | E2: INR | F2: 0.0555 | G2: largest dividend-paying REITs; Bagmane (no distribution yet) excluded
B3: EMBASSY | C3: Embassy Office Parks REIT | D3: 425.95 | E3: INR | F3: 0.0514
B4: MINDSPACE | C4: Mindspace Business Parks REIT | D4: 305.43 | E4: INR | F4: 0.0523
C5: Average — top 3 | F5: =AVERAGE(F2:F4) -> 0.053066667
A7: USA | B7: WELL | C7: Welltower | D7: 163.86 | E7: US$ | F7: 0.0127
B8: PLD | C8: Prologis | D8: 134.72 | E8: US$ | F8: 0.0304
B9: EQIX | C9: Equinix | D9: 102.06 | E9: US$ | F9: 0.0203
C10: Average — top 3 | F10: =AVERAGE(F7:F9) -> 0.021133333
A12: Japan | B12: 8951 | C12: Nippon Building Fund | D12: 1050 | E12: JPY | F12: 0.0412
B13: 8952 | C13: Japan Real Estate Investment | D13: 868.2 | E13: JPY | F13: 0.0432
B14: 3283 | C14: Nippon Prologis REIT | D14: 748.31 | E14: JPY | F14: 0.0435
C15: Average — top 3 | F15: =AVERAGE(F12:F14) -> 0.042633333
A17: Australia | B17: GMG | C17: Goodman Group | D17: 60.16 | E17: A$ | F17: 0.0103 | G17: Vicinity has overtaken Stockland (A$9.4bn) for #3
B18: SCG | C18: Scentre Group | D18: 20.11 | E18: A$ | F18: 0.0467
B19: VCX | C19: Vicinity Centres | D19: 11.93 | E19: A$ | F19: 0.0482
C20: Average — top 3 | F20: =AVERAGE(F17:F19) -> 0.035066667
A22: Singapore | B22: C38U | C22: CapitaLand Integrated Commercial Trust | D22: 18.13 | E22: S$ | F22: 0.0523
B23: A17U | C23: CapitaLand Ascendas REIT | D23: 12.48 | E23: S$ | F23: 0.06
B24: N2IU | C24: Mapletree Pan Asia Commercial Trust | D24: 6.71 | E24: S$ | F24: 0.0628
C25: Average — top 3 | F25: =AVERAGE(F22:F24) -> 0.058366667
A27: UK | B27: SGRO | C27: SEGRO | D27: 10.15 | E27: GBP | F27: 0.0414
B28: LAND | C28: Land Securities | D28: 4.78 | E28: GBP | F28: 0.0685
B29: BLND | C29: British Land | D29: 3.96 | E29: GBP | F29: 0.0578
C30: Average — top 3 | F30: =AVERAGE(F27:F29) -> 0.0559
A32: Hong Kong | B32: 0823 | C32: Link REIT | D32: 103.91 | E32: HK$ | F32: 0.0654
B33: 2778 | C33: Champion REIT | D33: 12.67 | E33: HK$ | F33: 0.0613
B34: 0778 | C34: Fortune REIT | D34: 9.4 | E34: HK$ | F34: 0.0726
C35: Average — top 3 | F35: =AVERAGE(F32:F34) -> 0.066433333
A37: Malaysia | B37: KLCC | C37: KLCCP Stapled Group | D37: 16.14 | E37: RM | F37: 0.0526
B38: IGBREIT | C38: IGB REIT | D38: 12.03 | E38: RM | F38: 0.0427
B39: SUNREIT | C39: Sunway REIT | D39: 7.6 | E39: RM | F39: 0.0646
C40: Average — top 3 | F40: =AVERAGE(F37:F39) -> 0.0533
A42: Top 3 = three largest REITs by market cap per market. Source: stockanalysis.com, retrieved 10 Jul 2026 (delayed quotes on non-US exchanges; as-of dates range Apr–Jul 2026). Fortune REIT market cap computed from units x price.
